Workbook
Name Año1: INICIO!$B$28
Name Año2: INICIO!$C$28
Name Año3: INICIO!$D$28
Name Año4: INICIO!$E$28
Name Año5: INICIO!$F$28
Name Producto1: INICIO!$B$40
Name Producto10: INICIO!$B$49
Name Producto11: INICIO!$B$50
Name Producto12: INICIO!$B$51
Name Producto13: INICIO!$B$52
Name Producto14: INICIO!$B$53
Name Producto15: INICIO!$B$54
Name Producto2: INICIO!$B$41
Name Producto3: INICIO!$B$42
Name Producto4: INICIO!$B$43
Name Producto5: INICIO!$B$44
Name Producto6: INICIO!$B$45
Name Producto7: INICIO!$B$46
Name Producto8: INICIO!$B$47
Name Producto9: INICIO!$B$48

Sheet INICIO
A9: Información General
A10: NOMBRE DE LA EMPRESA | B10: TIZA
A11: TIPO DE SOCIEDAD | B11: S.A.S
A12: AÑO DE INICIO DE OPERACIONES | B12: 2027
A13: PAÍS DONDE ESTAN LOS CLIENTES | B13: COLOMBIA
A14: MONEDA DE REFERENCIA | B14: COP
A17: Información general sobre los estudiantes a cargo del proyecto y socios adicionales
A18: NOMBRE DEL SOCIO | B18: TIPO DE SOCIO | C18: PARTICIPACIÓN
A19: Danna Sanchez | B19: ESTUDIANTE | C19: 0.25
A20: Sergio Nieto | B20: ESTUDIANTE | C20: 0.25
A21: Daniel Martin | B21: ESTUDIANTE | C21: 0.25
A22: Christian Morales | B22: ESTUDIANTE | C22: 0.25
A23: INVERSOR 5
A24: INVERSOR 6
A26: Variables Macroeconómicas y otros datos de interés
A27: VARIABLES | B27: AÑO
B28: =B12 -> 2027 | C28: =B28+1 -> 2028 | D28: =C28+1 -> 2029 | E28: =D28+1 -> 2030 | F28: =E28+1 -> 2031
A29: Tasa de cambio proyectada (COP/USD) | B29: 4150 | C29: 4280 | D29: 4410 | E29: 4410 | F29: 4410
A30: Inflación Anual Esperada | B30: 0.05 | C30: 0.042 | D30: 0.038 | E30: 0.035 | F30: 0.033
A31: Tasa de Crecimiento de la Industria (proyectada) | B31: =(12%*50%)+(4%*50%) -> 0.08 | C31: =(12%*50%)+(4%*50%) -> 0.08 | D31: =(12%*50%)+(4%*50%) -> 0.08 | E31: =(12%*50%)+(4%*50%) -> 0.08 | F31: =(12%*50%)+(4%*50%) -> 0.08
A32: Salario Mínimo Mensual Legal Vigente proyectado | B32: 1856000 | C32: 1949000 | D32: 2036000 | E32: 2118000 | F32: 2203000
A33: Auxilio de Transporte Legal Proyectado | B33: 268000 | C33: 282000 | D33: 294000 | E33: 306000 | F33: 318000
A34: Tasa del Impuesto de Renta Esperada | B34: 0.35 | C34: 0.35 | D34: 0.35 | E34: 0.35 | F34: 0.35
A39: PORTAFOLIO DE PRODUCTOS Y/O SERVICIOS | B39: NOMBRE DEL PRODUCTO O SERVICIO
A40: PRODUCTO O SERVICIO 1 | B40: Suscripcion Freemium
A41: PRODUCTO O SERVICIO 2 | B41: Suscripcion Premium
A42: PRODUCTO O SERVICIO 3
A43: PRODUCTO O SERVICIO 4
A44: PRODUCTO O SERVICIO 5
A45: PRODUCTO O SERVICIO 6
A46: PRODUCTO O SERVICIO 7
A47: PRODUCTO O SERVICIO 8
A48: PRODUCTO O SERVICIO 9
A49: PRODUCTO O SERVICIO 10
A50: PRODUCTO O SERVICIO 11
A51: PRODUCTO O SERVICIO 12
A52: PRODUCTO O SERVICIO 13
A53: PRODUCTO O SERVICIO 14
A54: PRODUCTO O SERVICIO 15
A56: GASTOS PREOPERATIVOS | B56: AÑO
...

Sheet INGRESOS
B1: =CONCATENATE(INICIO!$B$10," ",INICIO!$B$11) -> TIZA S.A.S
B5: PRESUPUESTO DE VENTAS
A9: PLAZO DE COBRO | B9: =Año1 -> 2027 | N9: =Año2 -> 2028 | Z9: =Año3 -> 2029 | AL9: =Año4 -> 2030 | AX9: =Año5 -> 2031
B10: Mes 1 | C10: Mes 2 | D10: Mes 3 | E10: Mes 4 | F10: Mes 5 | G10: Mes 6 | H10: Mes 7 | I10: Mes 8 | J10: Mes 9 | K10: Mes 10 | L10: Mes 11 | M10: Mes 12 | N10: Mes 13 | O10: Mes 14 | P10: Mes 15 | Q10: Mes 16 | R10: Mes 17 | S10: Mes 18 | T10: Mes 19 | U10: Mes 20 | V10: Mes 21 | W10: Mes 22 | X10: Mes 23 | Y10: Mes 24 | Z10: Mes 25 | AA10: Mes 26 | AB10: Mes 27 | AC10: Mes 28 | AD10: Mes 29 | AE10: Mes 30 | AF10: Mes 31 | AG10: Mes 32 | AH10: Mes 33 | AI10: Mes 34 | AJ10: Mes 35 | AK10: Mes 36 | AL10: Mes 37 | AM10: Mes 38 | AN10: Mes 39 | AO10: Mes 40 | AP10: Mes 41 | AQ10: Mes 42 | AR10: Mes 43 | AS10: Mes 44 | AT10: Mes 45 | AU10: Mes 46 | AV10: Mes 47 | AW10: Mes 48 | AX10: Mes 49 | AY10: Mes 50 | AZ10: Mes 51 | BA10: Mes 52 | BB10: Mes 53 | BC10: Mes 54 | BD10: Mes 55 | BE10: Mes 56 | BF10: Mes 57 | BG10: Mes 58 | BH10: Mes 59 | BI10: Mes 60
A11: Plazo que otorgará a los clientes para que le paguen (en días) | B11: 0 | C11: 0 | D11: 0 | E11: 0 | F11: 0 | G11: 0 | H11: 0 | I11: 0 | J11: 0 | K11: 0 | L11: 0 | M11: 0 | N11: 0 | O11: 0 | P11: 0 | Q11: 0 | R11: 0 | S11: 0 | T11: 0 | U11: 0 | V11: 0 | W11: 0 | X11: 0 | Y11: 0 | Z11: 0 | AA11: 0 | AB11: 0 | AC11: 0 | AD11: 0 | AE11: 0 | AF11: 0 | AG11: 0 | AH11: 0 | AI11: 0 | AJ11: 0 | AK11: 0 | AL11: 0 | AM11: 0 | AN11: 0 | AO11: 0 | AP11: 0 | AQ11: 0 | AR11: 0 | AS11: 0 | AT11: 0 | AU11: 0 | AV11: 0 | AW11: 0 | AX11: 0 | AY11: 0 | AZ11: 0 | BA11: 0 | BB11: 0 | BC11: 0 | BD11: 0 | BE11: 0 | BF11: 0 | BG11: 0 | BH11: 0 | BI11: 0
A13: TOTAL INGRESOS | B13: =Año1 -> 2027 | N13: =Año2 -> 2028 | Z13: =Año3 -> 2029 | AL13: =Año4 -> 2030 | AX13: =Año5 -> 2031
B14: =B10 -> Mes 1 | C14: =C10 -> Mes 2 | D14: =D10 -> Mes 3 | E14: =E10 -> Mes 4 | F14: =F10 -> Mes 5 | G14: =G10 -> Mes 6 | H14: =H10 -> Mes 7 | I14: =I10 -> Mes 8 | ... BI14: =BI10 -> Mes 60
A15: =CONCATENATE("Total ingresos por ventas del producto o servicio"," ",Producto1) -> Total ingresos por ventas del producto o servicio Suscripcion Freemium | B15: 0 | C15: 0 | D15: 0 | E15: 0 | F15: 0 | G15: 0 | H15: 0 | I15: 0 | J15: 0 | K15: 0 | L15: 0 | M15: 0 | N15: 0 | O15: 0 | P15: 0 | Q15: 0 | R15: 0 | S15: 0 | T15: 0 | U15: 0 | V15: 0 | W15: 0 | X15: 0 | Y15: 0 | Z15: 0 | AA15: 0 | AB15: 0 | AC15: 0 | AD15: 0 | AE15: 0 | AF15: 0 | AG15: 0 | AH15: 0 | AI15: 0 | AJ15: 0 | AK15: 0 | AL15: 0 | AM15: 0 | AN15: 0 | AO15: 0 | AP15: 0 | AQ15: 0 | AR15: 0 | AS15: 0 | AT15: 0 | AU15: 0 | AV15: 0 | AW15: 0 | AX15: 0
A16: =CONCATENATE("Total ingresos por ventas del producto o servicio"," ",Producto2) -> Total ingresos por ventas del producto o servicio Suscripcion Premium | B16: 400000 | C16: 600000 | D16: 880000 | E16: 1200000 | F16: 1520000 | G16: 1800000 | H16: 2200000 | I16: 2600000 | J16: 3000000 | K16: 3400000 | L16: 3800000 | M16: 4400000 | N16: 5000000 | O16: 5800000 | P16: 6600000 | Q16: 7400000 | R16: 8400000 | S16: 9400000 | T16: 10400000 | U16: 11600000 | V16: 12800000 | W16: 14000000 | X16: 15200000 | Y16: 16800000 | Z16: 18400000 | AA16: 20000000 | AB16: 21800000 | AC16: 23600000 | AD16: 25600000 | AE16: 27600000 | AF16: 29800000 | AG16: 32000000 | AH16: 34400000 | AI16: 36800000 | AJ16: 39200000 | AK16: 42000000 | AL16: 44800000 | AM16: 47600000 | AN16: 50400000 | AO16: 53600000 | AP16: 56800000 | AQ16: 60000000 | AR16: 63200000 | AS16: 66400000 | AT16: 69600000 | AU16: 73200000 | AV16: 76800000 | AW16: 80800000 | AX16: 84800000
A17: =CONCATENATE("Total ingresos por ventas del producto o servicio"," ",Producto3) -> Total ingresos por ventas del producto o servicio
A18: =CONCATENATE("Total ingresos por ventas del producto o servicio"," ",Producto4) -> Total ingresos por ventas del producto o servicio
A19: =CONCATENATE("Total ingresos por ventas del producto o servicio"," ",Producto5) -> Total ingresos por ventas del producto o servicio
A20: =CONCATENATE("Total ingresos por ventas del producto o servicio"," ",Producto6) -> Total ingresos por ventas del producto o servicio
A21: =CONCATENATE("Total ingresos por ventas del producto o servicio"," ",Producto7) -> Total ingresos por ventas del producto o servicio
A22: =CONCATENATE("Total ingresos por ventas del producto o servicio"," ",Producto8) -> Total ingresos por ventas del producto o servicio
A23: =CONCATENATE("Total ingresos por ventas del producto o servicio"," ",Producto9) -> Total ingresos por ventas del producto o servicio
A24: =CONCATENATE("Total ingresos por ventas del producto o servicio"," ",Producto10) -> Total ingresos por ventas del producto o servicio
A25: =CONCATENATE("Total ingresos por ventas del producto o servicio"," ",Producto11) -> Total ingresos por ventas del producto o servicio
A26: =CONCATENATE("Total ingresos por ventas del producto o servicio"," ",Producto12) -> Total ingresos por ventas del producto o servicio
A27: =CONCATENATE("Total ingresos por ventas del producto o servicio"," ",Producto13) -> Total ingresos por ventas del producto o servicio
A28: =CONCATENATE("Total ingresos por ventas del producto o servicio"," ",Producto14) -> Total ingresos por ventas del producto o servicio
A29: =CONCATENATE("Total ingresos por ventas del producto o servicio"," ",Producto15) -> Total ingresos por ventas del producto o servicio
A30: TOTAL INGRESOS POR VENTAS | B30: =SUM(B15:B29) -> 400000 | C30: =SUM(C15:C29) -> 600000 | D30: =SUM(D15:D29) -> 880000 | E30: =SUM(E15:E29) -> 1200000 | F30: =SUM(F15:F29) -> 1520000 | G30: =SUM(G15:G29) -> 1800000 | H30: =SUM(H15:H29) -> 2200000 | I30: =SUM(I15:I29) -> 2600000 | ... BI30: =SUM(BI15:BI29) -> 0
A33: Plantilla Realizada por María Teresa Macías Joven
A34: Universidad de La Sabana
A35: Versión 2021
A36: ®Todos los derechos reservados
A37: Si desea utilizar esta plantilla por fuera del programa Expo-Empresarial, clase de proyecto empresarial de la Universidad de La Sabana, asegúrese de poseer los derechos de uso por parte de la autora de la plantilla, con una autorización clara, expresa y por escrito.

Sheet COSTOS
B1: =CONCATENATE(INICIO!$B$10," ",INICIO!$B$11) -> TIZA S.A.S
B5: PRESUPUESTO DE COSTOS
A8: PRONÓSTICO DE COSTOS RELACIONADOS A LA PRODUCCIÓN DEL PRODUCTO O SERVICIO | B8: =Año1 -> 2027 | N8: =Año2 -> 2028 | Z8: =Año3 -> 2029 | AL8: =Año4 -> 2030 | AX8: =Año5 -> 2031
B9: Mes 1 | C9: Mes 2 | D9: Mes 3 | E9: Mes 4 | F9: Mes 5 | G9: Mes 6 | H9: Mes 7 | I9: Mes 8 | J9: Mes 9 | K9: Mes 10 | L9: Mes 11 | M9: Mes 12 | N9: Mes 13 | O9: Mes 14 | P9: Mes 15 | Q9: Mes 16 | R9: Mes 17 | S9: Mes 18 | T9: Mes 19 | U9: Mes 20 | V9: Mes 21 | W9: Mes 22 | X9: Mes 23 | Y9: Mes 24 | Z9: Mes 25 | AA9: Mes 26 | AB9: Mes 27 | AC9: Mes 28 | AD9: Mes 29 | AE9: Mes 30 | AF9: Mes 31 | AG9: Mes 32 | AH9: Mes 33 | AI9: Mes 34 | AJ9: Mes 35 | AK9: Mes 36 | AL9: Mes 37 | AM9: Mes 38 | AN9: Mes 39 | AO9: Mes 40 | AP9: Mes 41 | AQ9: Mes 42 | AR9: Mes 43 | AS9: Mes 44 | AT9: Mes 45 | AU9: Mes 46 | AV9: Mes 47 | AW9: Mes 48 | AX9: Mes 49 | AY9: Mes 50 | AZ9: Mes 51 | BA9: Mes 52 | BB9: Mes 53 | BC9: Mes 54 | BD9: Mes 55 | BE9: Mes 56 | BF9: Mes 57 | BG9: Mes 58 | BH9: Mes 59 | BI9: Mes 60
A10: Suscripcion Geminy - API Key | B10: 48140 | C10: 51460 | D10: 56108 | E10: 61420 | F10: 66732 | G10: 71380 | H10: 78020 | I10: 84660 | J10: 91300 | K10: 97940 | L10: 104580 | M10: 114540 | N10: 128400 | O10: 142096 | P10: 155792 | Q10: 169488 | R10: 186608 | S10: 203728 | T10: 220848 | U10: 241392 | V10: 261936 | W10: 282480 | X10: 303024 | Y10: 330416 | Z10: 368676 | AA10: 396900 | AB10: 428652 | AC10: 460404 | AD10: 495684 | AE10: 530964 | AF10: 569772 | AG10: 608580 | AH10: 650916 | AI10: 693252 | AJ10: 735588 | AK10: 784980 | AL10: 834372 | AM10: 883764 | AN10: 933156 | AO10: 989604 | AP10: 1046052 | AQ10: 1102500 | AR10: 1158948 | AS10: 1215396 | AT10: 1271844 | AU10: 1335348 | AV10: 1398852 | AW10: 1469412 | AX10: 1539972
A11: Dominio Web | B11: 5187 | C11: 5187 | D11: 5187 | E11: 5187 | F11: 5187 | G11: 5187 | H11: 5187 | I11: 5187 | J11: 5187 | K11: 5187 | L11: 5187 | M11: 5187 | N11: 5350 | O11: 5350 | P11: 5350 | Q11: 5350 | R11: 5350 | S11: 5350 | T11: 5350 | U11: 5350 | V11: 5350 | W11: 5350 | X11: 5350 | Y11: 5350 | Z11: 5512 | AA11: 5512 | AB11: 5512 | AC11: 5512 | AD11: 5512 | AE11: 5512 | AF11: 5512 | AG11: 5512 | AH11: 5512 | AI11: 5512 | AJ11: 5512 | AK11: 5512 | AL11: 5512 | AM11: 5512 | AN11: 5512 | AO11: 5512 | AP11: 5512 | AQ11: 5512 | AR11: 5512 | AS11: 5512 | AT11: 5512 | AU11: 5512 | AV11: 5512 | AW11: 5512 | AX11: 5512
A12: Suscripcion Supabase | B12: 0 | C12: 0 | D12: 0 | E12: 0 | F12: 0 | G12: 0 | H12: 103750 | I12: 103750 | J12: 103750 | K12: 103750 | L12: 103750 | M12: 103750 | N12: 107000 | O12: 107000 | P12: 107000 | Q12: 107000 | R12: 107000 | S12: 107000 | T12: 107000 | U12: 107000 | V12: 107000 | W12: 107000 | X12: 107000 | Y12: 107000 | Z12: 220500 | AA12: 220500 | AB12: 220500 | AC12: 220500 | AD12: 220500 | AE12: 220500 | AF12: 220500 | AG12: 220500 | AH12: 220500 | AI12: 220500 | AJ12: 220500 | AK12: 220500 | AL12: 220500 | AM12: 220500 | AN12: 220500 | AO12: 220500 | AP12: 220500 | AQ12: 220500 | AR12: 220500 | AS12: 220500 | AT12: 220500 | AU12: 220500 | AV12: 220500 | AW12: 220500 | AX12: 220500
A13: Internet (uso de internet en operaciones) | B13: 68000 | C13: 68000 | D13: 68000 | E13: 68000 | F13: 68000 | G13: 68000 | H13: 68000 | I13: 68000 | J13: 68000 | K13: 68000 | L13: 68000 | M13: 68000 | N13: 71200 | O13: 71200 | P13: 71200 | Q13: 71200 | R13: 71200 | S13: 71200 | T13: 71200 | U13: 71200 | V13: 71200 | W13: 71200 | X13: 71200 | Y13: 71200 | Z13: 74400 | AA13: 74400 | AB13: 74400 | AC13: 74400 | AD13: 74400 | AE13: 74400 | AF13: 74400 | AG13: 74400 | AH13: 74400 | AI13: 74400 | AJ13: 74400 | AK13: 74400 | AL13: 77600 | AM13: 77600 | AN13: 77600 | AO13: 77600 | AP13: 77600 | AQ13: 77600 | AR13: 77600 | AS13: 77600 | AT13: 77600 | AU13: 77600 | AV13: 77600 | AW13: 77600 | AX13: 80800
A14: Enel | B14: 48000 | C14: 48000 | D14: 48000 | E14: 48000 | F14: 48000 | G14: 48000 | H14: 48000 | I14: 48000 | J14: 48000 | K14: 48000 | L14: 48000 | M14: 48000 | N14: 50400 | O14: 50400 | P14: 50400 | Q14: 50400 | R14: 50400 | S14: 50400 | T14: 50400 | U14: 50400 | V14: 50400 | W14: 50400 | X14: 50400 | Y14: 50400 | Z14: 52800 | AA14: 52800 | AB14: 52800 | AC14: 52800 | AD14: 52800 | AE14: 52800 | AF14: 52800 | AG14: 52800 | AH14: 52800 | AI14: 52800 | AJ14: 52800 | AK14: 52800 | AL14: 55200 | AM14: 55200 | AN14: 55200 | AO14: 55200 | AP14: 55200 | AQ14: 55200 | AR14: 55200 | AS14: 55200 | AT14: 55200 | AU14: 55200 | AV14: 55200 | AW14: 55200 | AX14: 57600
A25: TOTAL PRONOSTICO DE COSTOS | B25: =SUM(B10:B24) -> 169327 | C25: =SUM(C10:C24) -> 172647 | D25: =SUM(D10:D24) -> 177295 | E25: =SUM(E10:E24) -> 182607 | F25: =SUM(F10:F24) -> 187919 | G25: =SUM(G10:G24) -> 192567 | H25: =SUM(H10:H24) -> 302957 | I25: =SUM(I10:I24) -> 309597 | ... BI25: =SUM(BI10:BI24) -> 0
A28: PRONOSTICO NOMINA OPERATIVA | B28: =Año1 -> 2027 | N28: =Año2 -> 2028 | Z28: =Año3 -> 2029 | AL28: =Año4 -> 2030 | AX28: =Año5 -> 2031
B29: =B9 -> Mes 1 | C29: =C9 -> Mes 2 | D29: =D9 -> Mes 3 | E29: =E9 -> Mes 4 | F29: =F9 -> Mes 5 | G29: =G9 -> Mes 6 | H29: =H9 -> Mes 7 | I29: =I9 -> Mes 8 | ... BI29: =BI9 -> Mes 60
A30: Cargo | B30: Salario mensual | C30: Salario mensual | D30: Salario mensual | E30: Salario mensual | F30: Salario mensual | G30: Salario mensual | H30: Salario mensual | I30: Salario mensual | J30: Salario mensual | K30: Salario mensual | L30: Salario mensual | M30: Salario mensual | N30: Salario mensual | O30: Salario mensual | P30: Salario mensual | Q30: Salario mensual | R30: Salario mensual | S30: Salario mensual | T30: Salario mensual | U30: Salario mensual | V30: Salario mensual | W30: Salario mensual | X30: Salario mensual | Y30: Salario mensual | Z30: Salario mensual | AA30: Salario mensual | AB30: Salario mensual | AC30: Salario mensual | AD30: Salario mensual | AE30: Salario mensual | AF30: Salario mensual | AG30: Salario mensual | AH30: Salario mensual | AI30: Salario mensual | AJ30: Salario mensual | AK30: Salario mensual | AL30: Salario mensual | AM30: Salario mensual | AN30: Salario mensual | AO30: Salario mensual | AP30: Salario mensual | AQ30: Salario mensual | AR30: Salario mensual | AS30: Salario mensual | AT30: Salario mensual | AU30: Salario mensual | AV30: Salario mensual | AW30: Salario mensual | AX30: Salario mensual | AY30: Salario mensual | AZ30: Salario mensual | BA30: Salario mensual | BB30: Salario mensual | BC30: Salario mensual | BD30: Salario mensual | BE30: Salario mensual | BF30: Salario mensual | BG30: Salario mensual | BH30: Salario mensual | BI30: Salario mensual
A31: Desarrollador Junior 1 | B31: 3500000 | C31: 3500000 | D31: 3500000 | E31: 3500000 | F31: 3500000 | G31: 3500000 | H31: 3500000 | I31: 3500000 | J31: 3500000 | K31: 3500000 | L31: 3500000 | M31: 3500000 | N31: 3700000 | O31: 3700000 | P31: 3700000 | Q31: 3700000 | R31: 3700000 | S31: 3700000 | T31: 3700000 | U31: 3700000 | V31: 3700000 | W31: 3700000 | X31: 3700000 | Y31: 3700000 | Z31: 3900000 | AA31: 3900000 | AB31: 3900000 | AC31: 3900000 | AD31: 3900000 | AE31: 3900000 | AF31: 3900000 | AG31: 3900000 | AH31: 3900000 | AI31: 3900000 | AJ31: 3900000 | AK31: 3900000 | AL31: 4100000 | AM31: 4100000 | AN31: 4100000 | AO31: 4100000 | AP31: 4100000 | AQ31: 4100000 | AR31: 4100000 | AS31: 4100000 | AT31: 4100000 | AU31: 4100000 | AV31: 4100000 | AW31: 4100000 | AX31: 4100000
A32: Desarrollador Junior 2 | B32: 0 | C32: 0 | D32: 0 | E32: 0 | F32: 0 | G32: 0 | H32: 0 | I32: 0 | J32: 0 | K32: 0 | L32: 0 | M32: 0 | N32: 3700000 | O32: 3700000 | P32: 3700000 | Q32: 3700000 | R32: 3700000 | S32: 3700000 | T32: 3700000 | U32: 3700000 | V32: 3700000 | W32: 3700000 | X32: 3700000 | Y32: 3700000 | Z32: 3900000 | AA32: 3900000 | AB32: 3900000 | AC32: 3900000 | AD32: 3900000 | AE32: 3900000 | AF32: 3900000 | AG32: 3900000 | AH32: 3900000 | AI32: 3900000 | AJ32: 3900000 | AK32: 3900000 | AL32: 4100000 | AM32: 4100000 | AN32: 4100000 | AO32: 4100000 | AP32: 4100000 | AQ32: 4100000 | AR32: 4100000 | AS32: 4100000 | AT32: 4100000 | AU32: 4100000 | AV32: 4100000 | AW32: 4100000 | AX32: 4100000
A33: Desarrollador Mid | B33: 0 | C33: 0 | D33: 0 | E33: 0 | F33: 0 | G33: 0 | H33: 0 | I33: 0 | J33: 0 | K33: 0 | L33: 0 | M33: 0 | N33: 0 | O33: 0 | P33: 0 | Q33: 0 | R33: 0 | S33: 0 | T33: 0 | U33: 0 | V33: 0 | W33: 0 | X33: 0 | Y33: 0 | Z33: 5500000 | AA33: 5500000 | AB33: 5500000 | AC33: 5500000 | AD33: 5500000 | AE33: 5500000 | AF33: 5500000 | AG33: 5500000 | AH33: 5500000 | AI33: 5500000 | AJ33: 5500000 | AK33: 5500000 | AL33: 5800000 | AM33: 5800000 | AN33: 5800000 | AO33: 5800000 | AP33: 5800000 | AQ33: 5800000 | AR33: 5800000 | AS33: 5800000 | AT33: 5800000 | AU33: 5800000 | AV33: 5800000 | AW33: 5800000 | AX33: 5800000
A34: Desarrollador Senior | B34: 0 | C34: 0 | D34: 0 | E34: 0 | F34: 0 | G34: 0 | H34: 0 | I34: 0 | J34: 0 | K34: 0 | L34: 0 | M34: 0 | N34: 0 | O34: 0 | P34: 0 | Q34: 0 | R34: 0 | S34: 0 | T34: 0 | U34: 0 | V34: 0 | W34: 0 | X34: 0 | Y34: 0 | Z34: 0 | AA34: 0 | AB34: 0 | AC34: 0 | AD34: 0 | AE34: 0 | AF34: 0 | AG34: 0 | AH34: 0 | AI34: 0 | AJ34: 0 | AK34: 0 | AL34: 7500000 | AM34: 7500000 | AN34: 7500000 | AO34: 7500000 | AP34: 7500000 | AQ34: 7500000 | AR34: 7500000 | AS34: 7500000 | AT34: 7500000 | AU34: 7500000 | AV34: 7500000 | AW34: 7500000 | AX34: 7500000
A47: TOTAL NÓMINA OPERATIVA | B47: =SUM(B31:B46) -> 3500000 | C47: =SUM(C31:C46) -> 3500000 | D47: =SUM(D31:D46) -> 3500000 | E47: =SUM(E31:E46) -> 3500000 | F47: =SUM(F31:F46) -> 3500000 | G47: =SUM(G31:G46) -> 3500000 | H47: =SUM(H31:H46) -> 3500000 | I47: =SUM(I31:I46) -> 3500000 | ... BI47: =SUM(BI31:BI46) -> 0
A48: Auxilios de Transporte | B48: =IF(B31=0,0,IF(B31<INICIO!$B$32*2,INICIO!$B$33,0))+IF(B32=0,0,IF(B32<INICIO!$B$32*2,INICIO!$B$33,0))+IF(B33=0,0,IF(B33<INICIO!$B$32*2,INICIO!$B$33,0))+IF(B34=0,0,IF(B34<INICIO!$B$32*2,INICIO!$B$33,0))+IF(B35=0,0,IF(B35<INICIO!$B$32*2,INICIO!$B$33,0))+IF(B36=0,0,IF(B36<INICIO!$B$32*2,INICIO!$B$33,0))+IF(B37=0,0,IF(B37<INICIO!$B$32*2,INICIO!$B$33,0))+IF(B38=0,0,IF(B38<INICIO!$B$32*2,INICIO!$B$33,0))+IF(B39=0,0,IF(B39<INICIO!$B$32*2,INICIO!$B$33,0))+IF(B40=0,0,IF(B40<INICIO!$B$32*2,INICIO!$B$33,0))+IF(B41=0,0,IF(B41<INICIO!$B$32*2,INICIO!$B$33,0))+IF(B42=0,0,IF(B42<INICIO!$B$32*2,INICIO!$B$33,0))+IF(B43=0,0,IF(B43<INICIO!$B$32*2,INICIO!$B$33,0))+IF(B44=0,0,IF(B44<INICIO!$B$32*2,INICIO!$B$33,0))+IF(B45=0,0,IF(B45<INICIO!$B$32*2,INICIO!$B$33,0))+IF(B46=0,0,IF(B46<INICIO!$B$32*2,INICIO!$B$33,0)) -> 268000 | C48: =IF(C31=0,0,IF(C31<INICIO!$B$32*2,INICIO!$B$33,0))+IF(C32=0,0,IF(C32<INICIO!$B$32*2,INICIO!$B$33,0))+IF(C33=0,0,IF(C33<INICIO!$B$32*2,INICIO!$B$33,0))+IF(C34=0,0,IF(C34<INICIO!$B$32*2,INICIO!$B$33,0))+IF(C35=0,0,IF(C35<INICIO!$B$32*2,INICIO!$B$33,0))+IF(C36=0,0,IF(C36<INICIO!$B$32*2,INICIO!$B$33,0))+IF(C37=0,0,IF(C37<INICIO!$B$32*2,INICIO!$B$33,0))+IF(C38=0,0,IF(C38<INICIO!$B$32*2,INICIO!$B$33,0))+IF(C39=0,0,IF(C39<INICIO!$B$32*2,INICIO!$B$33,0))+IF(C40=0,0,IF(C40<INICIO!$B$32*2,INICIO!$B$33,0))+IF(C41=0,0,IF(C41<INICIO!$B$32*2,INICIO!$B$33,0))+IF(C42=0,0,IF(C42<INICIO!$B$32*2,INICIO!$B$33,0))+IF(C43=0,0,IF(C43<INICIO!$B$32*2,INICIO!$B$33,0))+IF(C44=0,0,IF(C44<INICIO!$B$32*2,INICIO!$B$33,0))+IF(C45=0,0,IF(C45<INICIO!$B$32*2,INICIO!$B$33,0))+IF(C46=0,0,IF(C46<INICIO!$B$32*2,INICIO!$B$33,0)) -> 268000 | D48: =IF(D31=0,0,IF(D31<INICIO!$B$32*2,INICIO!$B$33,0))+IF(D32=0,0,IF(D32<INICIO!$B$32*2,INICIO!$B$33,0))+IF(D33=0,0,IF(D33<INICIO!$B$32*2,INICIO!$B$33,0))+IF(D34=0,0,IF(D34<INICIO!$B$32*2,INICIO!$B$33,0))+IF(D35=0,0,IF(D35<INICIO!$B$32*2,INICIO!$B$33,0))+IF(D36=0,0,IF(D36<INICIO!$B$32*2,INICIO!$B$33,0))+IF(D37=0,0,IF(D37<INICIO!$B$32*2,INICIO!$B$33,0))+IF(D38=0,0,IF(D38<INICIO!$B$32*2,INICIO!$B$33,0))+IF(D39=0,0,IF(D39<INICIO!$B$32*2,INICIO!$B$33,0))+IF(D40=0,0,IF(D40<INICIO!$B$32*2,INICIO!$B$33,0))+IF(D41=0,0,IF(D41<INICIO!$B$32*2,INICIO!$B$33,0))+IF(D42=0,0,IF(D42<INICIO!$B$32*2,INICIO!$B$33,0))+IF(D43=0,0,IF(D43<INICIO!$B$32*2,INICIO!$B$33,0))+IF(D44=0,0,IF(D44<INICIO!$B$32*2,INICIO!$B$33,0))+IF(D45=0,0,IF(D45<INICIO!$B$32*2,INICIO!$B$33,0))+IF(D46=0,0,IF(D46<INICIO!$B$32*2,INICIO!$B$33,0)) -> 268000 | E48: =IF(E31=0,0,IF(E31<INICIO!$B$32*2,INICIO!$B$33,0))+IF(E32=0,0,IF(E32<INICIO!$B$32*2,INICIO!$B$33,0))+IF(E33=0,0,IF(E33<INICIO!$B$32*2,INICIO!$B$33,0))+IF(E34=0,0,IF(E34<INICIO!$B$32*2,INICIO!$B$33,0))+IF(E35=0,0,IF(E35<INICIO!$B$32*2,INICIO!$B$33,0))+IF(E36=0,0,IF(E36<INICIO!$B$32*2,INICIO!$B$33,0))+IF(E37=0,0,IF(E37<INICIO!$B$32*2,INICIO!$B$33,0))+IF(E38=0,0,IF(E38<INICIO!$B$32*2,INICIO!$B$33,0))+IF(E39=0,0,IF(E39<INICIO!$B$32*2,INICIO!$B$33,0))+IF(E40=0,0,IF(E40<INICIO!$B$32*2,INICIO!$B$33,0))+IF(E41=0,0,IF(E41<INICIO!$B$32*2,INICIO!$B$33,0))+IF(E42=0,0,IF(E42<INICIO!$B$32*2,INICIO!$B$33,0))+IF(E43=0,0,IF(E43<INICIO!$B$32*2,INICIO!$B$33,0))+IF(E44=0,0,IF(E44<INICIO!$B$32*2,INICIO!$B$33,0))+IF(E45=0,0,IF(E45<INICIO!$B$32*2,INICIO!$B$33,0))+IF(E46=0,0,IF(E46<INICIO!$B$32*2,INICIO!$B$33,0)) -> 268000 | F48: =IF(F31=0,0,IF(F31<INICIO!$B$32*2,INICIO!$B$33,0))+IF(F32=0,0,IF(F32<INICIO!$B$32*2,INICIO!$B$33,0))+IF(F33=0,0,IF(F33<INICIO!$B$32*2,INICIO!$B$33,0))+IF(F34=0,0,IF(F34<INICIO!$B$32*2,INICIO!$B$33,0))+IF(F35=0,0,IF(F35<INICIO!$B$32*2,INICIO!$B$33,0))+IF(F36=0,0,IF(F36<INICIO!$B$32*2,INICIO!$B$33,0))+IF(F37=0,0,IF(F37<INICIO!$B$32*2,INICIO!$B$33,0))+IF(F38=0,0,IF(F38<INICIO!$B$32*2,INICIO!$B$33,0))+IF(F39=0,0,IF(F39<INICIO!$B$32*2,INICIO!$B$33,0))+IF(F40=0,0,IF(F40<INICIO!$B$32*2,INICIO!$B$33,0))+IF(F41=0,0,IF(F41<INICIO!$B$32*2,INICIO!$B$33,0))+IF(F42=0,0,IF(F42<INICIO!$B$32*2,INICIO!$B$33,0))+IF(F43=0,0,IF(F43<INICIO!$B$32*2,INICIO!$B$33,0))+IF(F44=0,0,IF(F44<INICIO!$B$32*2,INICIO!$B$33,0))+IF(F45=0,0,IF(F45<INICIO!$B$32*2,INICIO!$B$33,0))+IF(F46=0,0,IF(F46<INICIO!$B$32*2,INICIO!$B$33,0)) -> 268000 | G48: =IF(G31=0,0,IF(G31<INICIO!$B$32*2,INICIO!$B$33,0))+IF(G32=0,0,IF(G32<INICIO!$B$32*2,INICIO!$B$33,0))+IF(G33=0,0,IF(G33<INICIO!$B$32*2,INICIO!$B$33,0))+IF(G34=0,0,IF(G34<INICIO!$B$32*2,INICIO!$B$33,0))+IF(G35=0,0,IF(G35<INICIO!$B$32*2,INICIO!$B$33,0))+IF(G36=0,0,IF(G36<INICIO!$B$32*2,INICIO!$B$33,0))+IF(G37=0,0,IF(G37<INICIO!$B$32*2,INICIO!$B$33,0))+IF(G38=0,0,IF(G38<INICIO!$B$32*2,INICIO!$B$33,0))+IF(G39=0,0,IF(G39<INICIO!$B$32*2,INICIO!$B$33,0))+IF(G40=0,0,IF(G40<INICIO!$B$32*2,INICIO!$B$33,0))+IF(G41=0,0,IF(G41<INICIO!$B$32*2,INICIO!$B$33,0))+IF(G42=0,0,IF(G42<INICIO!$B$32*2,INICIO!$B$33,0))+IF(G43=0,0,IF(G43<INICIO!$B$32*2,INICIO!$B$33,0))+IF(G44=0,0,IF(G44<INICIO!$B$32*2,INICIO!$B$33,0))+IF(G45=0,0,IF(G45<INICIO!$B$32*2,INICIO!$B$33,0))+IF(G46=0,0,IF(G46<INICIO!$B$32*2,INICIO!$B$33,0)) -> 268000 | H48: =IF(H31=0,0,IF(H31<INICIO!$B$32*2,INICIO!$B$33,0))+IF(H32=0,0,IF(H32<INICIO!$B$32*2,INICIO!$B$33,0))+IF(H33=0,0,IF(H33<INICIO!$B$32*2,INICIO!$B$33,0))+IF(H34=0,0,IF(H34<INICIO!$B$32*2,INICIO!$B$33,0))+IF(H35=0,0,IF(H35<INICIO!$B$32*2,INICIO!$B$33,0))+IF(H36=0,0,IF(H36<INICIO!$B$32*2,INICIO!$B$33,0))+IF(H37=0,0,IF(H37<INICIO!$B$32*2,INICIO!$B$33,0))+IF(H38=0,0,IF(H38<INICIO!$B$32*2,INICIO!$B$33,0))+IF(H39=0,0,IF(H39<INICIO!$B$32*2,INICIO!$B$33,0))+IF(H40=0,0,IF(H40<INICIO!$B$32*2,INICIO!$B$33,0))+IF(H41=0,0,IF(H41<INICIO!$B$32*2,INICIO!$B$33,0))+IF(H42=0,0,IF(H42<INICIO!$B$32*2,INICIO!$B$33,0))+IF(H43=0,0,IF(H43<INICIO!$B$32*2,INICIO!$B$33,0))+IF(H44=0,0,IF(H44<INICIO!$B$32*2,INICIO!$B$33,0))+IF(H45=0,0,IF(H45<INICIO!$B$32*2,INICIO!$B$33,0))+IF(H46=0,0,IF(H46<INICIO!$B$32*2,INICIO!$B$33,0)) -> 268000 | I48: =IF(I31=0,0,IF(I31<INICIO!$B$32*2,INICIO!$B$33,0))+IF(I32=0,0,IF(I32<INICIO!$B$32*2,INICIO!$B$33,0))+IF(I33=0,0,IF(I33<INICIO!$B$32*2,INICIO!$B$33,0))+IF(I34=0,0,IF(I34<INICIO!$B$32*2,INICIO!$B$33,0))+IF(I35=0,0,IF(I35<INICIO!$B$32*2,INICIO!$B$33,0))+IF(I36=0,0,IF(I36<INICIO!$B$32*2,INICIO!$B$33,0))+IF(I37=0,0,IF(I37<INICIO!$B$32*2,INICIO!$B$33,0))+IF(I38=0,0,IF(I38<INICIO!$B$32*2,INICIO!$B$33,0))+IF(I39=0,0,IF(I39<INICIO!$B$32*2,INICIO!$B$33,0))+IF(I40=0,0,IF(I40<INICIO!$B$32*2,INICIO!$B$33,0))+IF(I41=0,0,IF(I41<INICIO!$B$32*2,INICIO!$B$33,0))+IF(I42=0,0,IF(I42<INICIO!$B$32*2,INICIO!$B$33,0))+IF(I43=0,0,IF(I43<INICIO!$B$32*2,INICIO!$B$33,0))+IF(I44=0,0,IF(I44<INICIO!$B$32*2,INICIO!$B$33,0))+IF(I45=0,0,IF(I45<INICIO!$B$32*2,INICIO!$B$33,0))+IF(I46=0,0,IF(I46<INICIO!$B$32*2,INICIO!$B$33,0)) -> 268000 | ... M48: =IF(M31=0,0,IF(M31<INICIO!$B$32*2,INICIO!$B$33,0))+IF(M32=0,0,IF(M32<INICIO!$B$32*2,INICIO!$B$33,0))+IF(M33=0,0,IF(M33<INICIO!$B$32*2,INICIO!$B$33,0))+IF(M34=0,0,IF(M34<INICIO!$B$32*2,INICIO!$B$33,0))+IF(M35=0,0,IF(M35<INICIO!$B$32*2,INICIO!$B$33,0))+IF(M36=0,0,IF(M36<INICIO!$B$32*2,INICIO!$B$33,0))+IF(M37=0,0,IF(M37<INICIO!$B$32*2,INICIO!$B$33,0))+IF(M38=0,0,IF(M38<INICIO!$B$32*2,INICIO!$B$33,0))+IF(M39=0,0,IF(M39<INICIO!$B$32*2,INICIO!$B$33,0))+IF(M40=0,0,IF(M40<INICIO!$B$32*2,INICIO!$B$33,0))+IF(M41=0,0,IF(M41<INICIO!$B$32*2,INICIO!$B$33,0))+IF(M42=0,0,IF(M42<INICIO!$B$32*2,INICIO!$B$33,0))+IF(M43=0,0,IF(M43<INICIO!$B$32*2,INICIO!$B$33,0))+IF(M44=0,0,IF(M44<INICIO!$B$32*2,INICIO!$B$33,0))+IF(M45=0,0,IF(M45<INICIO!$B$32*2,INICIO!$B$33,0))+IF(M46=0,0,IF(M46<INICIO!$B$32*2,INICIO!$B$33,0)) -> 268000 | N48: =IF(N31=0,0,IF(N31<INICIO!$C$32*2,INICIO!$C$33,0))+IF(N32=0,0,IF(N32<INICIO!$C$32*2,INICIO!$C$33,0))+IF(N33=0,0,IF(N33<INICIO!$C$32*2,INICIO!$C$33,0))+IF(N34=0,0,IF(N34<INICIO!$C$32*2,INICIO!$C$33,0))+IF(N35=0,0,IF(N35<INICIO!$C$32*2,INICIO!$C$33,0))+IF(N36=0,0,IF(N36<INICIO!$C$32*2,INICIO!$C$33,0))+IF(N37=0,0,IF(N37<INICIO!$C$32*2,INICIO!$C$33,0))+IF(N38=0,0,IF(N38<INICIO!$C$32*2,INICIO!$C$33,0))+IF(N39=0,0,IF(N39<INICIO!$C$32*2,INICIO!$C$33,0))+IF(N40=0,0,IF(N40<INICIO!$C$32*2,INICIO!$C$33,0))+IF(N41=0,0,IF(N41<INICIO!$C$32*2,INICIO!$C$33,0))+IF(N42=0,0,IF(N42<INICIO!$C$32*2,INICIO!$C$33,0))+IF(N43=0,0,IF(N43<INICIO!$C$32*2,INICIO!$C$33,0))+IF(N44=0,0,IF(N44<INICIO!$C$32*2,INICIO!$C$33,0))+IF(N45=0,0,IF(N45<INICIO!$C$32*2,INICIO!$C$33,0))+IF(N46=0,0,IF(N46<INICIO!$C$32*2,INICIO!$C$33,0)) -> 564000 | O48: =IF(O31=0,0,IF(O31<INICIO!$C$32*2,INICIO!$C$33,0))+IF(O32=0,0,IF(O32<INICIO!$C$32*2,INICIO!$C$33,0))+IF(O33=0,0,IF(O33<INICIO!$C$32*2,INICIO!$C$33,0))+IF(O34=0,0,IF(O34<INICIO!$C$32*2,INICIO!$C$33,0))+IF(O35=0,0,IF(O35<INICIO!$C$32*2,INICIO!$C$33,0))+IF(O36=0,0,IF(O36<INICIO!$C$32*2,INICIO!$C$33,0))+IF(O37=0,0,IF(O37<INICIO!$C$32*2,INICIO!$C$33,0))+IF(O38=0,0,IF(O38<INICIO!$C$32*2,INICIO!$C$33,0))+IF(O39=0,0,IF(O39<INICIO!$C$32*2,INICIO!$C$33,0))+IF(O40=0,0,IF(O40<INICIO!$C$32*2,INICIO!$C$33,0))+IF(O41=0,0,IF(O41<INICIO!$C$32*2,INICIO!$C$33,0))+IF(O42=0,0,IF(O42<INICIO!$C$32*2,INICIO!$C$33,0))+IF(O43=0,0,IF(O43<INICIO!$C$32*2,INICIO!$C$33,0))+IF(O44=0,0,IF(O44<INICIO!$C$32*2,INICIO!$C$33,0))+IF(O45=0,0,IF(O45<INICIO!$C$32*2,INICIO!$C$33,0))+IF(O46=0,0,IF(O46<INICIO!$C$32*2,INICIO!$C$33,0)) -> 564000 | P48: =IF(P31=0,0,IF(P31<INICIO!$C$32*2,INICIO!$C$33,0))+IF(P32=0,0,IF(P32<INICIO!$C$32*2,INICIO!$C$33,0))+IF(P33=0,0,IF(P33<INICIO!$C$32*2,INICIO!$C$33,0))+IF(P34=0,0,IF(P34<INICIO!$C$32*2,INICIO!$C$33,0))+IF(P35=0,0,IF(P35<INICIO!$C$32*2,INICIO!$C$33,0))+IF(P36=0,0,IF(P36<INICIO!$C$32*2,INICIO!$C$33,0))+IF(P37=0,0,IF(P37<INICIO!$C$32*2,INICIO!$C$33,0))+IF(P38=0,0,IF(P38<INICIO!$C$32*2,INICIO!$C$33,0))+IF(P39=0,0,IF(P39<INICIO!$C$32*2,INICIO!$C$33,0))+IF(P40=0,0,IF(P40<INICIO!$C$32*2,INICIO!$C$33,0))+IF(P41=0,0,IF(P41<INICIO!$C$32*2,INICIO!$C$33,0))+IF(P42=0,0,IF(P42<INICIO!$C$32*2,INICIO!$C$33,0))+IF(P43=0,0,IF(P43<INICIO!$C$32*2,INICIO!$C$33,0))+IF(P44=0,0,IF(P44<INICIO!$C$32*2,INICIO!$C$33,0))+IF(P45=0,0,IF(P45<INICIO!$C$32*2,INICIO!$C$33,0))+IF(P46=0,0,IF(P46<INICIO!$C$32*2,INICIO!$C$33,0)) -> 564000 | Q48: =IF(Q31=0,0,IF(Q31<INICIO!$C$32*2,INICIO!$C$33,0))+IF(Q32=0,0,IF(Q32<INICIO!$C$32*2,INICIO!$C$33,0))+IF(Q33=0,0,IF(Q33<INICIO!$C$32*2,INICIO!$C$33,0))+IF(Q34=0,0,IF(Q34<INICIO!$C$32*2,INICIO!$C$33,0))+IF(Q35=0,0,IF(Q35<INICIO!$C$32*2,INICIO!$C$33,0))+IF(Q36=0,0,IF(Q36<INICIO!$C$32*2,INICIO!$C$33,0))+IF(Q37=0,0,IF(Q37<INICIO!$C$32*2,INICIO!$C$33,0))+IF(Q38=0,0,IF(Q38<INICIO!$C$32*2,INICIO!$C$33,0))+IF(Q39=0,0,IF(Q39<INICIO!$C$32*2,INICIO!$C$33,0))+IF(Q40=0,0,IF(Q40<INICIO!$C$32*2,INICIO!$C$33,0))+IF(Q41=0,0,IF(Q41<INICIO!$C$32*2,INICIO!$C$33,0))+IF(Q42=0,0,IF(Q42<INICIO!$C$32*2,INICIO!$C$33,0))+IF(Q43=0,0,IF(Q43<INICIO!$C$32*2,INICIO!$C$33,0))+IF(Q44=0,0,IF(Q44<INICIO!$C$32*2,INICIO!$C$33,0))+IF(Q45=0,0,IF(Q45<INICIO!$C$32*2,INICIO!$C$33,0))+IF(Q46=0,0,IF(Q46<INICIO!$C$32*2,INICIO!$C$33,0)) -> 564000 | R48: =IF(R31=0,0,IF(R31<INICIO!$C$32*2,INICIO!$C$33,0))+IF(R32=0,0,IF(R32<INICIO!$C$32*2,INICIO!$C$33,0))+IF(R33=0,0,IF(R33<INICIO!$C$32*2,INICIO!$C$33,0))+IF(R34=0,0,IF(R34<INICIO!$C$32*2,INICIO!$C$33,0))+IF(R35=0,0,IF(R35<INICIO!$C$32*2,INICIO!$C$33,0))+IF(R36=0,0,IF(R36<INICIO!$C$32*2,INICIO!$C$33,0))+IF(R37=0,0,IF(R37<INICIO!$C$32*2,INICIO!$C$33,0))+IF(R38=0,0,IF(R38<INICIO!$C$32*2,INICIO!$C$33,0))+IF(R39=0,0,IF(R39<INICIO!$C$32*2,INICIO!$C$33,0))+IF(R40=0,0,IF(R40<INICIO!$C$32*2,INICIO!$C$33,0))+IF(R41=0,0,IF(R41<INICIO!$C$32*2,INICIO!$C$33,0))+IF(R42=0,0,IF(R42<INICIO!$C$32*2,INICIO!$C$33,0))+IF(R43=0,0,IF(R43<INICIO!$C$32*2,INICIO!$C$33,0))+IF(R44=0,0,IF(R44<INICIO!$C$32*2,INICIO!$C$33,0))+IF(R45=0,0,IF(R45<INICIO!$C$32*2,INICIO!$C$33,0))+IF(R46=0,0,IF(R46<INICIO!$C$32*2,INICIO!$C$33,0)) -> 564000 | S48: =IF(S31=0,0,IF(S31<INICIO!$C$32*2,INICIO!$C$33,0))+IF(S32=0,0,IF(S32<INICIO!$C$32*2,INICIO!$C$33,0))+IF(S33=0,0,IF(S33<INICIO!$C$32*2,INICIO!$C$33,0))+IF(S34=0,0,IF(S34<INICIO!$C$32*2,INICIO!$C$33,0))+IF(S35=0,0,IF(S35<INICIO!$C$32*2,INICIO!$C$33,0))+IF(S36=0,0,IF(S36<INICIO!$C$32*2,INICIO!$C$33,0))+IF(S37=0,0,IF(S37<INICIO!$C$32*2,INICIO!$C$33,0))+IF(S38=0,0,IF(S38<INICIO!$C$32*2,INICIO!$C$33,0))+IF(S39=0,0,IF(S39<INICIO!$C$32*2,INICIO!$C$33,0))+IF(S40=0,0,IF(S40<INICIO!$C$32*2,INICIO!$C$33,0))+IF(S41=0,0,IF(S41<INICIO!$C$32*2,INICIO!$C$33,0))+IF(S42=0,0,IF(S42<INICIO!$C$32*2,INICIO!$C$33,0))+IF(S43=0,0,IF(S43<INICIO!$C$32*2,INICIO!$C$33,0))+IF(S44=0,0,IF(S44<INICIO!$C$32*2,INICIO!$C$33,0))+IF(S45=0,0,IF(S45<INICIO!$C$32*2,INICIO!$C$33,0))+IF(S46=0,0,IF(S46<INICIO!$C$32*2,INICIO!$C$33,0)) -> 564000 | T48: =IF(T31=0,0,IF(T31<INICIO!$C$32*2,INICIO!$C$33,0))+IF(T32=0,0,IF(T32<INICIO!$C$32*2,INICIO!$C$33,0))+IF(T33=0,0,IF(T33<INICIO!$C$32*2,INICIO!$C$33,0))+IF(T34=0,0,IF(T34<INICIO!$C$32*2,INICIO!$C$33,0))+IF(T35=0,0,IF(T35<INICIO!$C$32*2,INICIO!$C$33,0))+IF(T36=0,0,IF(T36<INICIO!$C$32*2,INICIO!$C$33,0))+IF(T37=0,0,IF(T37<INICIO!$C$32*2,INICIO!$C$33,0))+IF(T38=0,0,IF(T38<INICIO!$C$32*2,INICIO!$C$33,0))+IF(T39=0,0,IF(T39<INICIO!$C$32*2,INICIO!$C$33,0))+IF(T40=0,0,IF(T40<INICIO!$C$32*2,INICIO!$C$33,0))+IF(T41=0,0,IF(T41<INICIO!$C$32*2,INICIO!$C$33,0))+IF(T42=0,0,IF(T42<INICIO!$C$32*2,INICIO!$C$33,0))+IF(T43=0,0,IF(T43<INICIO!$C$32*2,INICIO!$C$33,0))+IF(T44=0,0,IF(T44<INICIO!$C$32*2,INICIO!$C$33,0))+IF(T45=0,0,IF(T45<INICIO!$C$32*2,INICIO!$C$33,0))+IF(T46=0,0,IF(T46<INICIO!$C$32*2,INICIO!$C$33,0)) -> 564000 | U48: =IF(U31=0,0,IF(U31<INICIO!$C$32*2,INICIO!$C$33,0))+IF(U32=0,0,IF(U32<INICIO!$C$32*2,INICIO!$C$33,0))+IF(U33=0,0,IF(U33<INICIO!$C$32*2,INICIO!$C$33,0))+IF(U34=0,0,IF(U34<INICIO!$C$32*2,INICIO!$C$33,0))+IF(U35=0,0,IF(U35<INICIO!$C$32*2,INICIO!$C$33,0))+IF(U36=0,0,IF(U36<INICIO!$C$32*2,INICIO!$C$33,0))+IF(U37=0,0,IF(U37<INICIO!$C$32*2,INICIO!$C$33,0))+IF(U38=0,0,IF(U38<INICIO!$C$32*2,INICIO!$C$33,0))+IF(U39=0,0,IF(U39<INICIO!$C$32*2,INICIO!$C$33,0))+IF(U40=0,0,IF(U40<INICIO!$C$32*2,INICIO!$C$33,0))+IF(U41=0,0,IF(U41<INICIO!$C$32*2,INICIO!$C$33,0))+IF(U42=0,0,IF(U42<INICIO!$C$32*2,INICIO!$C$33,0))+IF(U43=0,0,IF(U43<INICIO!$C$32*2,INICIO!$C$33,0))+IF(U44=0,0,IF(U44<INICIO!$C$32*2,INICIO!$C$33,0))+IF(U45=0,0,IF(U45<INICIO!$C$32*2,INICIO!$C$33,0))+IF(U46=0,0,IF(U46<INICIO!$C$32*2,INICIO!$C$33,0)) -> 564000 | ... Y48: =IF(Y31=0,0,IF(Y31<INICIO!$C$32*2,INICIO!$C$33,0))+IF(Y32=0,0,IF(Y32<INICIO!$C$32*2,INICIO!$C$33,0))+IF(Y33=0,0,IF(Y33<INICIO!$C$32*2,INICIO!$C$33,0))+IF(Y34=0,0,IF(Y34<INICIO!$C$32*2,INICIO!$C$33,0))+IF(Y35=0,0,IF(Y35<INICIO!$C$32*2,INICIO!$C$33,0))+IF(Y36=0,0,IF(Y36<INICIO!$C$32*2,INICIO!$C$33,0))+IF(Y37=0,0,IF(Y37<INICIO!$C$32*2,INICIO!$C$33,0))+IF(Y38=0,0,IF(Y38<INICIO!$C$32*2,INICIO!$C$33,0))+IF(Y39=0,0,IF(Y39<INICIO!$C$32*2,INICIO!$C$33,0))+IF(Y40=0,0,IF(Y40<INICIO!$C$32*2,INICIO!$C$33,0))+IF(Y41=0,0,IF(Y41<INICIO!$C$32*2,INICIO!$C$33,0))+IF(Y42=0,0,IF(Y42<INICIO!$C$32*2,INICIO!$C$33,0))+IF(Y43=0,0,IF(Y43<INICIO!$C$32*2,INICIO!$C$33,0))+IF(Y44=0,0,IF(Y44<INICIO!$C$32*2,INICIO!$C$33,0))+IF(Y45=0,0,IF(Y45<INICIO!$C$32*2,INICIO!$C$33,0))+IF(Y46=0,0,IF(Y46<INICIO!$C$32*2,INICIO!$C$33,0)) -> 564000 | Z48: =IF(Z31=0,0,IF(Z31<INICIO!$D$32*2,INICIO!$D$33,0))+IF(Z32=0,0,IF(Z32<INICIO!$D$32*2,INICIO!$D$33,0))+IF(Z33=0,0,IF(Z33<INICIO!$D$32*2,INICIO!$D$33,0))+IF(Z34=0,0,IF(Z34<INICIO!$D$32*2,INICIO!$D$33,0))+IF(Z35=0,0,IF(Z35<INICIO!$D$32*2,INICIO!$D$33,0))+IF(Z36=0,0,IF(Z36<INICIO!$D$32*2,INICIO!$D$33,0))+IF(Z37=0,0,IF(Z37<INICIO!$D$32*2,INICIO!$D$33,0))+IF(Z38=0,0,IF(Z38<INICIO!$D$32*2,INICIO!$D$33,0))+IF(Z39=0,0,IF(Z39<INICIO!$D$32*2,INICIO!$D$33,0))+IF(Z40=0,0,IF(Z40<INICIO!$D$32*2,INICIO!$D$33,0))+IF(Z41=0,0,IF(Z41<INICIO!$D$32*2,INICIO!$D$33,0))+IF(Z42=0,0,IF(Z42<INICIO!$D$32*2,INICIO!$D$33,0))+IF(Z43=0,0,IF(Z43<INICIO!$D$32*2,INICIO!$D$33,0))+IF(Z44=0,0,IF(Z44<INICIO!$D$32*2,INICIO!$D$33,0))+IF(Z45=0,0,IF(Z45<INICIO!$D$32*2,INICIO!$D$33,0))+IF(Z46=0,0,IF(Z46<INICIO!$D$32*2,INICIO!$D$33,0)) -> 588000 | AA48: =IF(AA31=0,0,IF(AA31<INICIO!$D$32*2,INICIO!$D$33,0))+IF(AA32=0,0,IF(AA32<INICIO!$D$32*2,INICIO!$D$33,0))+IF(AA33=0,0,IF(AA33<INICIO!$D$32*2,INICIO!$D$33,0))+IF(AA34=0,0,IF(AA34<INICIO!$D$32*2,INICIO!$D$33,0))+IF(AA35=0,0,IF(AA35<INICIO!$D$32*2,INICIO!$D$33,0))+IF(AA36=0,0,IF(AA36<INICIO!$D$32*2,INICIO!$D$33,0))+IF(AA37=0,0,IF(AA37<INICIO!$D$32*2,INICIO!$D$33,0))+IF(AA38=0,0,IF(AA38<INICIO!$D$32*2,INICIO!$D$33,0))+IF(AA39=0,0,IF(AA39<INICIO!$D$32*2,INICIO!$D$33,0))+IF(AA40=0,0,IF(AA40<INICIO!$D$32*2,INICIO!$D$33,0))+IF(AA41=0,0,IF(AA41<INICIO!$D$32*2,INICIO!$D$33,0))+IF(AA42=0,0,IF(AA42<INICIO!$D$32*2,INICIO!$D$33,0))+IF(AA43=0,0,IF(AA43<INICIO!$D$32*2,INICIO!$D$33,0))+IF(AA44=0,0,IF(AA44<INICIO!$D$32*2,INICIO!$D$33,0))+IF(AA45=0,0,IF(AA45<INICIO!$D$32*2,INICIO!$D$33,0))+IF(AA46=0,0,IF(AA46<INICIO!$D$32*2,INICIO!$D$33,0)) -> 588000 | AB48: =IF(AB31=0,0,IF(AB31<INICIO!$D$32*2,INICIO!$D$33,0))+IF(AB32=0,0,IF(AB32<INICIO!$D$32*2,INICIO!$D$33,0))+IF(AB33=0,0,IF(AB33<INICIO!$D$32*2,INICIO!$D$33,0))+IF(AB34=0,0,IF(AB34<INICIO!$D$32*2,INICIO!$D$33,0))+IF(AB35=0,0,IF(AB35<INICIO!$D$32*2,INICIO!$D$33,0))+IF(AB36=0,0,IF(AB36<INICIO!$D$32*2,INICIO!$D$33,0))+IF(AB37=0,0,IF(AB37<INICIO!$D$32*2,INICIO!$D$33,0))+IF(AB38=0,0,IF(AB38<INICIO!$D$32*2,INICIO!$D$33,0))+IF(AB39=0,0,IF(AB39<INICIO!$D$32*2,INICIO!$D$33,0))+IF(AB40=0,0,IF(AB40<INICIO!$D$32*2,INICIO!$D$33,0))+IF(AB41=0,0,IF(AB41<INICIO!$D$32*2,INICIO!$D$33,0))+IF(AB42=0,0,IF(AB42<INICIO!$D$32*2,INICIO!$D$33,0))+IF(AB43=0,0,IF(AB43<INICIO!$D$32*2,INICIO!$D$33,0))+IF(AB44=0,0,IF(AB44<INICIO!$D$32*2,INICIO!$D$33,0))+IF(AB45=0,0,IF(AB45<INICIO!$D$32*2,INICIO!$D$33,0))+IF(AB46=0,0,IF(AB46<INICIO!$D$32*2,INICIO!$D$33,0)) -> 588000 | AC48: =IF(AC31=0,0,IF(AC31<INICIO!$D$32*2,INICIO!$D$33,0))+IF(AC32=0,0,IF(AC32<INICIO!$D$32*2,INICIO!$D$33,0))+IF(AC33=0,0,IF(AC33<INICIO!$D$32*2,INICIO!$D$33,0))+IF(AC34=0,0,IF(AC34<INICIO!$D$32*2,INICIO!$D$33,0))+IF(AC35=0,0,IF(AC35<INICIO!$D$32*2,INICIO!$D$33,0))+IF(AC36=0,0,IF(AC36<INICIO!$D$32*2,INICIO!$D$33,0))+IF(AC37=0,0,IF(AC37<INICIO!$D$32*2,INICIO!$D$33,0))+IF(AC38=0,0,IF(AC38<INICIO!$D$32*2,INICIO!$D$33,0))+IF(AC39=0,0,IF(AC39<INICIO!$D$32*2,INICIO!$D$33,0))+IF(AC40=0,0,IF(AC40<INICIO!$D$32*2,INICIO!$D$33,0))+IF(AC41=0,0,IF(AC41<INICIO!$D$32*2,INICIO!$D$33,0))+IF(AC42=0,0,IF(AC42<INICIO!$D$32*2,INICIO!$D$33,0))+IF(AC43=0,0,IF(AC43<INICIO!$D$32*2,INICIO!$D$33,0))+IF(AC44=0,0,IF(AC44<INICIO!$D$32*2,INICIO!$D$33,0))+IF(AC45=0,0,IF(AC45<INICIO!$D$32*2,INICIO!$D$33,0))+IF(AC46=0,0,IF(AC46<INICIO!$D$32*2,INICIO!$D$33,0)) -> 588000 | AD48: =IF(AD31=0,0,IF(AD31<INICIO!$D$32*2,INICIO!$D$33,0))+IF(AD32=0,0,IF(AD32<INICIO!$D$32*2,INICIO!$D$33,0))+IF(AD33=0,0,IF(AD33<INICIO!$D$32*2,INICIO!$D$33,0))+IF(AD34=0,0,IF(AD34<INICIO!$D$32*2,INICIO!$D$33,0))+IF(AD35=0,0,IF(AD35<INICIO!$D$32*2,INICIO!$D$33,0))+IF(AD36=0,0,IF(AD36<INICIO!$D$32*2,INICIO!$D$33,0))+IF(AD37=0,0,IF(AD37<INICIO!$D$32*2,INICIO!$D$33,0))+IF(AD38=0,0,IF(AD38<INICIO!$D$32*2,INICIO!$D$33,0))+IF(AD39=0,0,IF(AD39<INICIO!$D$32*2,INICIO!$D$33,0))+IF(AD40=0,0,IF(AD40<INICIO!$D$32*2,INICIO!$D$33,0))+IF(AD41=0,0,IF(AD41<INICIO!$D$32*2,INICIO!$D$33,0))+IF(AD42=0,0,IF(AD42<INICIO!$D$32*2,INICIO!$D$33,0))+IF(AD43=0,0,IF(AD43<INICIO!$D$32*2,INICIO!$D$33,0))+IF(AD44=0,0,IF(AD44<INICIO!$D$32*2,INICIO!$D$33,0))+IF(AD45=0,0,IF(AD45<INICIO!$D$32*2,INICIO!$D$33,0))+IF(AD46=0,0,IF(AD46<INICIO!$D$32*2,INICIO!$D$33,0)) -> 588000 | AE48: =IF(AE31=0,0,IF(AE31<INICIO!$D$32*2,INICIO!$D$33,0))+IF(AE32=0,0,IF(AE32<INICIO!$D$32*2,INICIO!$D$33,0))+IF(AE33=0,0,IF(AE33<INICIO!$D$32*2,INICIO!$D$33,0))+IF(AE34=0,0,IF(AE34<INICIO!$D$32*2,INICIO!$D$33,0))+IF(AE35=0,0,IF(AE35<INICIO!$D$32*2,INICIO!$D$33,0))+IF(AE36=0,0,IF(AE36<INICIO!$D$32*2,INICIO!$D$33,0))+IF(AE37=0,0,IF(AE37<INICIO!$D$32*2,INICIO!$D$33,0))+IF(AE38=0,0,IF(AE38<INICIO!$D$32*2,INICIO!$D$33,0))+IF(AE39=0,0,IF(AE39<INICIO!$D$32*2,INICIO!$D$33,0))+IF(AE40=0,0,IF(AE40<INICIO!$D$32*2,INICIO!$D$33,0))+IF(AE41=0,0,IF(AE41<INICIO!$D$32*2,INICIO!$D$33,0))+IF(AE42=0,0,IF(AE42<INICIO!$D$32*2,INICIO!$D$33,0))+IF(AE43=0,0,IF(AE43<INICIO!$D$32*2,INICIO!$D$33,0))+IF(AE44=0,0,IF(AE44<INICIO!$D$32*2,INICIO!$D$33,0))+IF(AE45=0,0,IF(AE45<INICIO!$D$32*2,INICIO!$D$33,0))+IF(AE46=0,0,IF(AE46<INICIO!$D$32*2,INICIO!$D$33,0)) -> 588000 | AF48: =IF(AF31=0,0,IF(AF31<INICIO!$D$32*2,INICIO!$D$33,0))+IF(AF32=0,0,IF(AF32<INICIO!$D$32*2,INICIO!$D$33,0))+IF(AF33=0,0,IF(AF33<INICIO!$D$32*2,INICIO!$D$33,0))+IF(AF34=0,0,IF(AF34<INICIO!$D$32*2,INICIO!$D$33,0))+IF(AF35=0,0,IF(AF35<INICIO!$D$32*2,INICIO!$D$33,0))+IF(AF36=0,0,IF(AF36<INICIO!$D$32*2,INICIO!$D$33,0))+IF(AF37=0,0,IF(AF37<INICIO!$D$32*2,INICIO!$D$33,0))+IF(AF38=0,0,IF(AF38<INICIO!$D$32*2,INICIO!$D$33,0))+IF(AF39=0,0,IF(AF39<INICIO!$D$32*2,INICIO!$D$33,0))+IF(AF40=0,0,IF(AF40<INICIO!$D$32*2,INICIO!$D$33,0))+IF(AF41=0,0,IF(AF41<INICIO!$D$32*2,INICIO!$D$33,0))+IF(AF42=0,0,IF(AF42<INICIO!$D$32*2,INICIO!$D$33,0))+IF(AF43=0,0,IF(AF43<INICIO!$D$32*2,INICIO!$D$33,0))+IF(AF44=0,0,IF(AF44<INICIO!$D$32*2,INICIO!$D$33,0))+IF(AF45=0,0,IF(AF45<INICIO!$D$32*2,INICIO!$D$33,0))+IF(AF46=0,0,IF(AF46<INICIO!$D$32*2,INICIO!$D$33,0)) -> 588000 | AG48: =IF(AG31=0,0,IF(AG31<INICIO!$D$32*2,INICIO!$D$33,0))+IF(AG32=0,0,IF(AG32<INICIO!$D$32*2,INICIO!$D$33,0))+IF(AG33=0,0,IF(AG33<INICIO!$D$32*2,INICIO!$D$33,0))+IF(AG34=0,0,IF(AG34<INICIO!$D$32*2,INICIO!$D$33,0))+IF(AG35=0,0,IF(AG35<INICIO!$D$32*2,INICIO!$D$33,0))+IF(AG36=0,0,IF(AG36<INICIO!$D$32*2,INICIO!$D$33,0))+IF(AG37=0,0,IF(AG37<INICIO!$D$32*2,INICIO!$D$33,0))+IF(AG38=0,0,IF(AG38<INICIO!$D$32*2,INICIO!$D$33,0))+IF(AG39=0,0,IF(AG39<INICIO!$D$32*2,INICIO!$D$33,0))+IF(AG40=0,0,IF(AG40<INICIO!$D$32*2,INICIO!$D$33,0))+IF(AG41=0,0,IF(AG41<INICIO!$D$32*2,INICIO!$D$33,0))+IF(AG42=0,0,IF(AG42<INICIO!$D$32*2,INICIO!$D$33,0))+IF(AG43=0,0,IF(AG43<INICIO!$D$32*2,INICIO!$D$33,0))+IF(AG44=0,0,IF(AG44<INICIO!$D$32*2,INICIO!$D$33,0))+IF(AG45=0,0,IF(AG45<INICIO!$D$32*2,INICIO!$D$33,0))+IF(AG46=0,0,IF(AG46<INICIO!$D$32*2,INICIO!$D$33,0)) -> 588000 | ... AK48: =IF(AK31=0,0,IF(AK31<INICIO!$D$32*2,INICIO!$D$33,0))+IF(AK32=0,0,IF(AK32<INICIO!$D$32*2,INICIO!$D$33,0))+IF(AK33=0,0,IF(AK33<INICIO!$D$32*2,INICIO!$D$33,0))+IF(AK34=0,0,IF(AK34<INICIO!$D$32*2,INICIO!$D$33,0))+IF(AK35=0,0,IF(AK35<INICIO!$D$32*2,INICIO!$D$33,0))+IF(AK36=0,0,IF(AK36<INICIO!$D$32*2,INICIO!$D$33,0))+IF(AK37=0,0,IF(AK37<INICIO!$D$32*2,INICIO!$D$33,0))+IF(AK38=0,0,IF(AK38<INICIO!$D$32*2,INICIO!$D$33,0))+IF(AK39=0,0,IF(AK39<INICIO!$D$32*2,INICIO!$D$33,0))+IF(AK40=0,0,IF(AK40<INICIO!$D$32*2,INICIO!$D$33,0))+IF(AK41=0,0,IF(AK41<INICIO!$D$32*2,INICIO!$D$33,0))+IF(AK42=0,0,IF(AK42<INICIO!$D$32*2,INICIO!$D$33,0))+IF(AK43=0,0,IF(AK43<INICIO!$D$32*2,INICIO!$D$33,0))+IF(AK44=0,0,IF(AK44<INICIO!$D$32*2,INICIO!$D$33,0))+IF(AK45=0,0,IF(AK45<INICIO!$D$32*2,INICIO!$D$33,0))+IF(AK46=0,0,IF(AK46<INICIO!$D$32*2,INICIO!$D$33,0)) -> 588000 | AL48: =IF(AL31=0,0,IF(AL31<INICIO!$E$32*2,INICIO!$E$33,0))+IF(AL32=0,0,IF(AL32<INICIO!$E$32*2,INICIO!$E$33,0))+IF(AL33=0,0,IF(AL33<INICIO!$E$32*2,INICIO!$E$33,0))+IF(AL34=0,0,IF(AL34<INICIO!$E$32*2,INICIO!$E$33,0))+IF(AL35=0,0,IF(AL35<INICIO!$E$32*2,INICIO!$E$33,0))+IF(AL36=0,0,IF(AL36<INICIO!$E$32*2,INICIO!$E$33,0))+IF(AL37=0,0,IF(AL37<INICIO!$E$32*2,INICIO!$E$33,0))+IF(AL38=0,0,IF(AL38<INICIO!$E$32*2,INICIO!$E$33,0))+IF(AL39=0,0,IF(AL39<INICIO!$E$32*2,INICIO!$E$33,0))+IF(AL40=0,0,IF(AL40<INICIO!$E$32*2,INICIO!$E$33,0))+IF(AL41=0,0,IF(AL41<INICIO!$E$32*2,INICIO!$E$33,0))+IF(AL42=0,0,IF(AL42<INICIO!$E$32*2,INICIO!$E$33,0))+IF(AL43=0,0,IF(AL43<INICIO!$E$32*2,INICIO!$E$33,0))+IF(AL44=0,0,IF(AL44<INICIO!$E$32*2,INICIO!$E$33,0))+IF(AL45=0,0,IF(AL45<INICIO!$E$32*2,INICIO!$E$33,0))+IF(AL46=0,0,IF(AL46<INICIO!$E$32*2,INICIO!$E$33,0)) -> 612000 | AM48: =IF(AM31=0,0,IF(AM31<INICIO!$E$32*2,INICIO!$E$33,0))+IF(AM32=0,0,IF(AM32<INICIO!$E$32*2,INICIO!$E$33,0))+IF(AM33=0,0,IF(AM33<INICIO!$E$32*2,INICIO!$E$33,0))+IF(AM34=0,0,IF(AM34<INICIO!$E$32*2,INICIO!$E$33,0))+IF(AM35=0,0,IF(AM35<INICIO!$E$32*2,INICIO!$E$33,0))+IF(AM36=0,0,IF(AM36<INICIO!$E$32*2,INICIO!$E$33,0))+IF(AM37=0,0,IF(AM37<INICIO!$E$32*2,INICIO!$E$33,0))+IF(AM38=0,0,IF(AM38<INICIO!$E$32*2,INICIO!$E$33,0))+IF(AM39=0,0,IF(AM39<INICIO!$E$32*2,INICIO!$E$33,0))+IF(AM40=0,0,IF(AM40<INICIO!$E$32*2,INICIO!$E$33,0))+IF(AM41=0,0,IF(AM41<INICIO!$E$32*2,INICIO!$E$33,0))+IF(AM42=0,0,IF(AM42<INICIO!$E$32*2,INICIO!$E$33,0))+IF(AM43=0,0,IF(AM43<INICIO!$E$32*2,INICIO!$E$33,0))+IF(AM44=0,0,IF(AM44<INICIO!$E$32*2,INICIO!$E$33,0))+IF(AM45=0,0,IF(AM45<INICIO!$E$32*2,INICIO!$E$33,0))+IF(AM46=0,0,IF(AM46<INICIO!$E$32*2,INICIO!$E$33,0)) -> 612000 | AN48: =IF(AN31=0,0,IF(AN31<INICIO!$E$32*2,INICIO!$E$33,0))+IF(AN32=0,0,IF(AN32<INICIO!$E$32*2,INICIO!$E$33,0))+IF(AN33=0,0,IF(AN33<INICIO!$E$32*2,INICIO!$E$33,0))+IF(AN34=0,0,IF(AN34<INICIO!$E$32*2,INICIO!$E$33,0))+IF(AN35=0,0,IF(AN35<INICIO!$E$32*2,INICIO!$E$33,0))+IF(AN36=0,0,IF(AN36<INICIO!$E$32*2,INICIO!$E$33,0))+IF(AN37=0,0,IF(AN37<INICIO!$E$32*2,INICIO!$E$33,0))+IF(AN38=0,0,IF(AN38<INICIO!$E$32*2,INICIO!$E$33,0))+IF(AN39=0,0,IF(AN39<INICIO!$E$32*2,INICIO!$E$33,0))+IF(AN40=0,0,IF(AN40<INICIO!$E$32*2,INICIO!$E$33,0))+IF(AN41=0,0,IF(AN41<INICIO!$E$32*2,INICIO!$E$33,0))+IF(AN42=0,0,IF(AN42<INICIO!$E$32*2,INICIO!$E$33,0))+IF(AN43=0,0,IF(AN43<INICIO!$E$32*2,INICIO!$E$33,0))+IF(AN44=0,0,IF(AN44<INICIO!$E$32*2,INICIO!$E$33,0))+IF(AN45=0,0,IF(AN45<INICIO!$E$32*2,INICIO!$E$33,0))+IF(AN46=0,0,IF(AN46<INICIO!$E$32*2,INICIO!$E$33,0)) -> 612000 | AO48: =IF(AO31=0,0,IF(AO31<INICIO!$E$32*2,INICIO!$E$33,0))+IF(AO32=0,0,IF(AO32<INICIO!$E$32*2,INICIO!$E$33,0))+IF(AO33=0,0,IF(AO33<INICIO!$E$32*2,INICIO!$E$33,0))+IF(AO34=0,0,IF(AO34<INICIO!$E$32*2,INICIO!$E$33,0))+IF(AO35=0,0,IF(AO35<INICIO!$E$32*2,INICIO!$E$33,0))+IF(AO36=0,0,IF(AO36<INICIO!$E$32*2,INICIO!$E$33,0))+IF(AO37=0,0,IF(AO37<INICIO!$E$32*2,INICIO!$E$33,0))+IF(AO38=0,0,IF(AO38<INICIO!$E$32*2,INICIO!$E$33,0))+IF(AO39=0,0,IF(AO39<INICIO!$E$32*2,INICIO!$E$33,0))+IF(AO40=0,0,IF(AO40<INICIO!$E$32*2,INICIO!$E$33,0))+IF(AO41=0,0,IF(AO41<INICIO!$E$32*2,INICIO!$E$33,0))+IF(AO42=0,0,IF(AO42<INICIO!$E$32*2,INICIO!$E$33,0))+IF(AO43=0,0,IF(AO43<INICIO!$E$32*2,INICIO!$E$33,0))+IF(AO44=0,0,IF(AO44<INICIO!$E$32*2,INICIO!$E$33,0))+IF(AO45=0,0,IF(AO45<INICIO!$E$32*2,INICIO!$E$33,0))+IF(AO46=0,0,IF(AO46<INICIO!$E$32*2,INICIO!$E$33,0)) -> 612000 | AP48: =IF(AP31=0,0,IF(AP31<INICIO!$E$32*2,INICIO!$E$33,0))+IF(AP32=0,0,IF(AP32<INICIO!$E$32*2,INICIO!$E$33,0))+IF(AP33=0,0,IF(AP33<INICIO!$E$32*2,INICIO!$E$33,0))+IF(AP34=0,0,IF(AP34<INICIO!$E$32*2,INICIO!$E$33,0))+IF(AP35=0,0,IF(AP35<INICIO!$E$32*2,INICIO!$E$33,0))+IF(AP36=0,0,IF(AP36<INICIO!$E$32*2,INICIO!$E$33,0))+IF(AP37=0,0,IF(AP37<INICIO!$E$32*2,INICIO!$E$33,0))+IF(AP38=0,0,IF(AP38<INICIO!$E$32*2,INICIO!$E$33,0))+IF(AP39=0,0,IF(AP39<INICIO!$E$32*2,INICIO!$E$33,0))+IF(AP40=0,0,IF(AP40<INICIO!$E$32*2,INICIO!$E$33,0))+IF(AP41=0,0,IF(AP41<INICIO!$E$32*2,INICIO!$E$33,0))+IF(AP42=0,0,IF(AP42<INICIO!$E$32*2,INICIO!$E$33,0))+IF(AP43=0,0,IF(AP43<INICIO!$E$32*2,INICIO!$E$33,0))+IF(AP44=0,0,IF(AP44<INICIO!$E$32*2,INICIO!$E$33,0))+IF(AP45=0,0,IF(AP45<INICIO!$E$32*2,INICIO!$E$33,0))+IF(AP46=0,0,IF(AP46<INICIO!$E$32*2,INICIO!$E$33,0)) -> 612000 | AQ48: =IF(AQ31=0,0,IF(AQ31<INICIO!$E$32*2,INICIO!$E$33,0))+IF(AQ32=0,0,IF(AQ32<INICIO!$E$32*2,INICIO!$E$33,0))+IF(AQ33=0,0,IF(AQ33<INICIO!$E$32*2,INICIO!$E$33,0))+IF(AQ34=0,0,IF(AQ34<INICIO!$E$32*2,INICIO!$E$33,0))+IF(AQ35=0,0,IF(AQ35<INICIO!$E$32*2,INICIO!$E$33,0))+IF(AQ36=0,0,IF(AQ36<INICIO!$E$32*2,INICIO!$E$33,0))+IF(AQ37=0,0,IF(AQ37<INICIO!$E$32*2,INICIO!$E$33,0))+IF(AQ38=0,0,IF(AQ38<INICIO!$E$32*2,INICIO!$E$33,0))+IF(AQ39=0,0,IF(AQ39<INICIO!$E$32*2,INICIO!$E$33,0))+IF(AQ40=0,0,IF(AQ40<INICIO!$E$32*2,INICIO!$E$33,0))+IF(AQ41=0,0,IF(AQ41<INICIO!$E$32*2,INICIO!$E$33,0))+IF(AQ42=0,0,IF(AQ42<INICIO!$E$32*2,INICIO!$E$33,0))+IF(AQ43=0,0,IF(AQ43<INICIO!$E$32*2,INICIO!$E$33,0))+IF(AQ44=0,0,IF(AQ44<INICIO!$E$32*2,INICIO!$E$33,0))+IF(AQ45=0,0,IF(AQ45<INICIO!$E$32*2,INICIO!$E$33,0))+IF(AQ46=0,0,IF(AQ46<INICIO!$E$32*2,INICIO!$E$33,0)) -> 612000 | AR48: =IF(AR31=0,0,IF(AR31<INICIO!$E$32*2,INICIO!$E$33,0))+IF(AR32=0,0,IF(AR32<INICIO!$E$32*2,INICIO!$E$33,0))+IF(AR33=0,0,IF(AR33<INICIO!$E$32*2,INICIO!$E$33,0))+IF(AR34=0,0,IF(AR34<INICIO!$E$32*2,INICIO!$E$33,0))+IF(AR35=0,0,IF(AR35<INICIO!$E$32*2,INICIO!$E$33,0))+IF(AR36=0,0,IF(AR36<INICIO!$E$32*2,INICIO!$E$33,0))+IF(AR37=0,0,IF(AR37<INICIO!$E$32*2,INICIO!$E$33,0))+IF(AR38=0,0,IF(AR38<INICIO!$E$32*2,INICIO!$E$33,0))+IF(AR39=0,0,IF(AR39<INICIO!$E$32*2,INICIO!$E$33,0))+IF(AR40=0,0,IF(AR40<INICIO!$E$32*2,INICIO!$E$33,0))+IF(AR41=0,0,IF(AR41<INICIO!$E$32*2,INICIO!$E$33,0))+IF(AR42=0,0,IF(AR42<INICIO!$E$32*2,INICIO!$E$33,0))+IF(AR43=0,0,IF(AR43<INICIO!$E$32*2,INICIO!$E$33,0))+IF(AR44=0,0,IF(AR44<INICIO!$E$32*2,INICIO!$E$33,0))+IF(AR45=0,0,IF(AR45<INICIO!$E$32*2,INICIO!$E$33,0))+IF(AR46=0,0,IF(AR46<INICIO!$E$32*2,INICIO!$E$33,0)) -> 612000 | AS48: =IF(AS31=0,0,IF(AS31<INICIO!$E$32*2,INICIO!$E$33,0))+IF(AS32=0,0,IF(AS32<INICIO!$E$32*2,INICIO!$E$33,0))+IF(AS33=0,0,IF(AS33<INICIO!$E$32*2,INICIO!$E$33,0))+IF(AS34=0,0,IF(AS34<INICIO!$E$32*2,INICIO!$E$33,0))+IF(AS35=0,0,IF(AS35<INICIO!$E$32*2,INICIO!$E$33,0))+IF(AS36=0,0,IF(AS36<INICIO!$E$32*2,INICIO!$E$33,0))+IF(AS37=0,0,IF(AS37<INICIO!$E$32*2,INICIO!$E$33,0))+IF(AS38=0,0,IF(AS38<INICIO!$E$32*2,INICIO!$E$33,0))+IF(AS39=0,0,IF(AS39<INICIO!$E$32*2,INICIO!$E$33,0))+IF(AS40=0,0,IF(AS40<INICIO!$E$32*2,INICIO!$E$33,0))+IF(AS41=0,0,IF(AS41<INICIO!$E$32*2,INICIO!$E$33,0))+IF(AS42=0,0,IF(AS42<INICIO!$E$32*2,INICIO!$E$33,0))+IF(AS43=0,0,IF(AS43<INICIO!$E$32*2,INICIO!$E$33,0))+IF(AS44=0,0,IF(AS44<INICIO!$E$32*2,INICIO!$E$33,0))+IF(AS45=0,0,IF(AS45<INICIO!$E$32*2,INICIO!$E$33,0))+IF(AS46=0,0,IF(AS46<INICIO!$E$32*2,INICIO!$E$33,0)) -> 612000 | ... AW48: =IF(AW31=0,0,IF(AW31<INICIO!$E$32*2,INICIO!$E$33,0))+IF(AW32=0,0,IF(AW32<INICIO!$E$32*2,INICIO!$E$33,0))+IF(AW33=0,0,IF(AW33<INICIO!$E$32*2,INICIO!$E$33,0))+IF(AW34=0,0,IF(AW34<INICIO!$E$32*2,INICIO!$E$33,0))+IF(AW35=0,0,IF(AW35<INICIO!$E$32*2,INICIO!$E$33,0))+IF(AW36=0,0,IF(AW36<INICIO!$E$32*2,INICIO!$E$33,0))+IF(AW37=0,0,IF(AW37<INICIO!$E$32*2,INICIO!$E$33,0))+IF(AW38=0,0,IF(AW38<INICIO!$E$32*2,INICIO!$E$33,0))+IF(AW39=0,0,IF(AW39<INICIO!$E$32*2,INICIO!$E$33,0))+IF(AW40=0,0,IF(AW40<INICIO!$E$32*2,INICIO!$E$33,0))+IF(AW41=0,0,IF(AW41<INICIO!$E$32*2,INICIO!$E$33,0))+IF(AW42=0,0,IF(AW42<INICIO!$E$32*2,INICIO!$E$33,0))+IF(AW43=0,0,IF(AW43<INICIO!$E$32*2,INICIO!$E$33,0))+IF(AW44=0,0,IF(AW44<INICIO!$E$32*2,INICIO!$E$33,0))+IF(AW45=0,0,IF(AW45<INICIO!$E$32*2,INICIO!$E$33,0))+IF(AW46=0,0,IF(AW46<INICIO!$E$32*2,INICIO!$E$33,0)) -> 612000 | AX48: =IF(AX31=0,0,IF(AX31<INICIO!$F$32*2,INICIO!$F$33,0))+IF(AX32=0,0,IF(AX32<INICIO!$F$32*2,INICIO!$F$33,0))+IF(AX33=0,0,IF(AX33<INICIO!$F$32*2,INICIO!$F$33,0))+IF(AX34=0,0,IF(AX34<INICIO!$F$32*2,INICIO!$F$33,0))+IF(AX35=0,0,IF(AX35<INICIO!$F$32*2,INICIO!$F$33,0))+IF(AX36=0,0,IF(AX36<INICIO!$F$32*2,INICIO!$F$33,0))+IF(AX37=0,0,IF(AX37<INICIO!$F$32*2,INICIO!$F$33,0))+IF(AX38=0,0,IF(AX38<INICIO!$F$32*2,INICIO!$F$33,0))+IF(AX39=0,0,IF(AX39<INICIO!$F$32*2,INICIO!$F$33,0))+IF(AX40=0,0,IF(AX40<INICIO!$F$32*2,INICIO!$F$33,0))+IF(AX41=0,0,IF(AX41<INICIO!$F$32*2,INICIO!$F$33,0))+IF(AX42=0,0,IF(AX42<INICIO!$F$32*2,INICIO!$F$33,0))+IF(AX43=0,0,IF(AX43<INICIO!$F$32*2,INICIO!$F$33,0))+IF(AX44=0,0,IF(AX44<INICIO!$F$32*2,INICIO!$F$33,0))+IF(AX45=0,0,IF(AX45<INICIO!$F$32*2,INICIO!$F$33,0))+IF(AX46=0,0,IF(AX46<INICIO!$F$32*2,INICIO!$F$33,0)) -> 636000 | AY48: =IF(AY31=0,0,IF(AY31<INICIO!$F$32*2,INICIO!$F$33,0))+IF(AY32=0,0,IF(AY32<INICIO!$F$32*2,INICIO!$F$33,0))+IF(AY33=0,0,IF(AY33<INICIO!$F$32*2,INICIO!$F$33,0))+IF(AY34=0,0,IF(AY34<INICIO!$F$32*2,INICIO!$F$33,0))+IF(AY35=0,0,IF(AY35<INICIO!$F$32*2,INICIO!$F$33,0))+IF(AY36=0,0,IF(AY36<INICIO!$F$32*2,INICIO!$F$33,0))+IF(AY37=0,0,IF(AY37<INICIO!$F$32*2,INICIO!$F$33,0))+IF(AY38=0,0,IF(AY38<INICIO!$F$32*2,INICIO!$F$33,0))+IF(AY39=0,0,IF(AY39<INICIO!$F$32*2,INICIO!$F$33,0))+IF(AY40=0,0,IF(AY40<INICIO!$F$32*2,INICIO!$F$33,0))+IF(AY41=0,0,IF(AY41<INICIO!$F$32*2,INICIO!$F$33,0))+IF(AY42=0,0,IF(AY42<INICIO!$F$32*2,INICIO!$F$33,0))+IF(AY43=0,0,IF(AY43<INICIO!$F$32*2,INICIO!$F$33,0))+IF(AY44=0,0,IF(AY44<INICIO!$F$32*2,INICIO!$F$33,0))+IF(AY45=0,0,IF(AY45<INICIO!$F$32*2,INICIO!$F$33,0))+IF(AY46=0,0,IF(AY46<INICIO!$F$32*2,INICIO!$F$33,0)) -> 0 | AZ48: =IF(AZ31=0,0,IF(AZ31<INICIO!$F$32*2,INICIO!$F$33,0))+IF(AZ32=0,0,IF(AZ32<INICIO!$F$32*2,INICIO!$F$33,0))+IF(AZ33=0,0,IF(AZ33<INICIO!$F$32*2,INICIO!$F$33,0))+IF(AZ34=0,0,IF(AZ34<INICIO!$F$32*2,INICIO!$F$33,0))+IF(AZ35=0,0,IF(AZ35<INICIO!$F$32*2,INICIO!$F$33,0))+IF(AZ36=0,0,IF(AZ36<INICIO!$F$32*2,INICIO!$F$33,0))+IF(AZ37=0,0,IF(AZ37<INICIO!$F$32*2,INICIO!$F$33,0))+IF(AZ38=0,0,IF(AZ38<INICIO!$F$32*2,INICIO!$F$33,0))+IF(AZ39=0,0,IF(AZ39<INICIO!$F$32*2,INICIO!$F$33,0))+IF(AZ40=0,0,IF(AZ40<INICIO!$F$32*2,INICIO!$F$33,0))+IF(AZ41=0,0,IF(AZ41<INICIO!$F$32*2,INICIO!$F$33,0))+IF(AZ42=0,0,IF(AZ42<INICIO!$F$32*2,INICIO!$F$33,0))+IF(AZ43=0,0,IF(AZ43<INICIO!$F$32*2,INICIO!$F$33,0))+IF(AZ44=0,0,IF(AZ44<INICIO!$F$32*2,INICIO!$F$33,0))+IF(AZ45=0,0,IF(AZ45<INICIO!$F$32*2,INICIO!$F$33,0))+IF(AZ46=0,0,IF(AZ46<INICIO!$F$32*2,INICIO!$F$33,0)) -> 0 | BA48: =IF(BA31=0,0,IF(BA31<INICIO!$F$32*2,INICIO!$F$33,0))+IF(BA32=0,0,IF(BA32<INICIO!$F$32*2,INICIO!$F$33,0))+IF(BA33=0,0,IF(BA33<INICIO!$F$32*2,INICIO!$F$33,0))+IF(BA34=0,0,IF(BA34<INICIO!$F$32*2,INICIO!$F$33,0))+IF(BA35=0,0,IF(BA35<INICIO!$F$32*2,INICIO!$F$33,0))+IF(BA36=0,0,IF(BA36<INICIO!$F$32*2,INICIO!$F$33,0))+IF(BA37=0,0,IF(BA37<INICIO!$F$32*2,INICIO!$F$33,0))+IF(BA38=0,0,IF(BA38<INICIO!$F$32*2,INICIO!$F$33,0))+IF(BA39=0,0,IF(BA39<INICIO!$F$32*2,INICIO!$F$33,0))+IF(BA40=0,0,IF(BA40<INICIO!$F$32*2,INICIO!$F$33,0))+IF(BA41=0,0,IF(BA41<INICIO!$F$32*2,INICIO!$F$33,0))+IF(BA42=0,0,IF(BA42<INICIO!$F$32*2,INICIO!$F$33,0))+IF(BA43=0,0,IF(BA43<INICIO!$F$32*2,INICIO!$F$33,0))+IF(BA44=0,0,IF(BA44<INICIO!$F$32*2,INICIO!$F$33,0))+IF(BA45=0,0,IF(BA45<INICIO!$F$32*2,INICIO!$F$33,0))+IF(BA46=0,0,IF(BA46<INICIO!$F$32*2,INICIO!$F$33,0)) -> 0 | BB48: =IF(BB31=0,0,IF(BB31<INICIO!$F$32*2,INICIO!$F$33,0))+IF(BB32=0,0,IF(BB32<INICIO!$F$32*2,INICIO!$F$33,0))+IF(BB33=0,0,IF(BB33<INICIO!$F$32*2,INICIO!$F$33,0))+IF(BB34=0,0,IF(BB34<INICIO!$F$32*2,INICIO!$F$33,0))+IF(BB35=0,0,IF(BB35<INICIO!$F$32*2,INICIO!$F$33,0))+IF(BB36=0,0,IF(BB36<INICIO!$F$32*2,INICIO!$F$33,0))+IF(BB37=0,0,IF(BB37<INICIO!$F$32*2,INICIO!$F$33,0))+IF(BB38=0,0,IF(BB38<INICIO!$F$32*2,INICIO!$F$33,0))+IF(BB39=0,0,IF(BB39<INICIO!$F$32*2,INICIO!$F$33,0))+IF(BB40=0,0,IF(BB40<INICIO!$F$32*2,INICIO!$F$33,0))+IF(BB41=0,0,IF(BB41<INICIO!$F$32*2,INICIO!$F$33,0))+IF(BB42=0,0,IF(BB42<INICIO!$F$32*2,INICIO!$F$33,0))+IF(BB43=0,0,IF(BB43<INICIO!$F$32*2,INICIO!$F$33,0))+IF(BB44=0,0,IF(BB44<INICIO!$F$32*2,INICIO!$F$33,0))+IF(BB45=0,0,IF(BB45<INICIO!$F$32*2,INICIO!$F$33,0))+IF(BB46=0,0,IF(BB46<INICIO!$F$32*2,INICIO!$F$33,0)) -> 0 | BC48: =IF(BC31=0,0,IF(BC31<INICIO!$F$32*2,INICIO!$F$33,0))+IF(BC32=0,0,IF(BC32<INICIO!$F$32*2,INICIO!$F$33,0))+IF(BC33=0,0,IF(BC33<INICIO!$F$32*2,INICIO!$F$33,0))+IF(BC34=0,0,IF(BC34<INICIO!$F$32*2,INICIO!$F$33,0))+IF(BC35=0,0,IF(BC35<INICIO!$F$32*2,INICIO!$F$33,0))+IF(BC36=0,0,IF(BC36<INICIO!$F$32*2,INICIO!$F$33,0))+IF(BC37=0,0,IF(BC37<INICIO!$F$32*2,INICIO!$F$33,0))+IF(BC38=0,0,IF(BC38<INICIO!$F$32*2,INICIO!$F$33,0))+IF(BC39=0,0,IF(BC39<INICIO!$F$32*2,INICIO!$F$33,0))+IF(BC40=0,0,IF(BC40<INICIO!$F$32*2,INICIO!$F$33,0))+IF(BC41=0,0,IF(BC41<INICIO!$F$32*2,INICIO!$F$33,0))+IF(BC42=0,0,IF(BC42<INICIO!$F$32*2,INICIO!$F$33,0))+IF(BC43=0,0,IF(BC43<INICIO!$F$32*2,INICIO!$F$33,0))+IF(BC44=0,0,IF(BC44<INICIO!$F$32*2,INICIO!$F$33,0))+IF(BC45=0,0,IF(BC45<INICIO!$F$32*2,INICIO!$F$33,0))+IF(BC46=0,0,IF(BC46<INICIO!$F$32*2,INICIO!$F$33,0)) -> 0 | BD48: =IF(BD31=0,0,IF(BD31<INICIO!$F$32*2,INICIO!$F$33,0))+IF(BD32=0,0,IF(BD32<INICIO!$F$32*2,INICIO!$F$33,0))+IF(BD33=0,0,IF(BD33<INICIO!$F$32*2,INICIO!$F$33,0))+IF(BD34=0,0,IF(BD34<INICIO!$F$32*2,INICIO!$F$33,0))+IF(BD35=0,0,IF(BD35<INICIO!$F$32*2,INICIO!$F$33,0))+IF(BD36=0,0,IF(BD36<INICIO!$F$32*2,INICIO!$F$33,0))+IF(BD37=0,0,IF(BD37<INICIO!$F$32*2,INICIO!$F$33,0))+IF(BD38=0,0,IF(BD38<INICIO!$F$32*2,INICIO!$F$33,0))+IF(BD39=0,0,IF(BD39<INICIO!$F$32*2,INICIO!$F$33,0))+IF(BD40=0,0,IF(BD40<INICIO!$F$32*2,INICIO!$F$33,0))+IF(BD41=0,0,IF(BD41<INICIO!$F$32*2,INICIO!$F$33,0))+IF(BD42=0,0,IF(BD42<INICIO!$F$32*2,INICIO!$F$33,0))+IF(BD43=0,0,IF(BD43<INICIO!$F$32*2,INICIO!$F$33,0))+IF(BD44=0,0,IF(BD44<INICIO!$F$32*2,INICIO!$F$33,0))+IF(BD45=0,0,IF(BD45<INICIO!$F$32*2,INICIO!$F$33,0))+IF(BD46=0,0,IF(BD46<INICIO!$F$32*2,INICIO!$F$33,0)) -> 0 | BE48: =IF(BE31=0,0,IF(BE31<INICIO!$F$32*2,INICIO!$F$33,0))+IF(BE32=0,0,IF(BE32<INICIO!$F$32*2,INICIO!$F$33,0))+IF(BE33=0,0,IF(BE33<INICIO!$F$32*2,INICIO!$F$33,0))+IF(BE34=0,0,IF(BE34<INICIO!$F$32*2,INICIO!$F$33,0))+IF(BE35=0,0,IF(BE35<INICIO!$F$32*2,INICIO!$F$33,0))+IF(BE36=0,0,IF(BE36<INICIO!$F$32*2,INICIO!$F$33,0))+IF(BE37=0,0,IF(BE37<INICIO!$F$32*2,INICIO!$F$33,0))+IF(BE38=0,0,IF(BE38<INICIO!$F$32*2,INICIO!$F$33,0))+IF(BE39=0,0,IF(BE39<INICIO!$F$32*2,INICIO!$F$33,0))+IF(BE40=0,0,IF(BE40<INICIO!$F$32*2,INICIO!$F$33,0))+IF(BE41=0,0,IF(BE41<INICIO!$F$32*2,INICIO!$F$33,0))+IF(BE42=0,0,IF(BE42<INICIO!$F$32*2,INICIO!$F$33,0))+IF(BE43=0,0,IF(BE43<INICIO!$F$32*2,INICIO!$F$33,0))+IF(BE44=0,0,IF(BE44<INICIO!$F$32*2,INICIO!$F$33,0))+IF(BE45=0,0,IF(BE45<INICIO!$F$32*2,INICIO!$F$33,0))+IF(BE46=0,0,IF(BE46<INICIO!$F$32*2,INICIO!$F$33,0)) -> 0 | ... BI48: =IF(BI31=0,0,IF(BI31<INICIO!$F$32*2,INICIO!$F$33,0))+IF(BI32=0,0,IF(BI32<INICIO!$F$32*2,INICIO!$F$33,0))+IF(BI33=0,0,IF(BI33<INICIO!$F$32*2,INICIO!$F$33,0))+IF(BI34=0,0,IF(BI34<INICIO!$F$32*2,INICIO!$F$33,0))+IF(BI35=0,0,IF(BI35<INICIO!$F$32*2,INICIO!$F$33,0))+IF(BI36=0,0,IF(BI36<INICIO!$F$32*2,INICIO!$F$33,0))+IF(BI37=0,0,IF(BI37<INICIO!$F$32*2,INICIO!$F$33,0))+IF(BI38=0,0,IF(BI38<INICIO!$F$32*2,INICIO!$F$33,0))+IF(BI39=0,0,IF(BI39<INICIO!$F$32*2,INICIO!$F$33,0))+IF(BI40=0,0,IF(BI40<INICIO!$F$32*2,INICIO!$F$33,0))+IF(BI41=0,0,IF(BI41<INICIO!$F$32*2,INICIO!$F$33,0))+IF(BI42=0,0,IF(BI42<INICIO!$F$32*2,INICIO!$F$33,0))+IF(BI43=0,0,IF(BI43<INICIO!$F$32*2,INICIO!$F$33,0))+IF(BI44=0,0,IF(BI44<INICIO!$F$32*2,INICIO!$F$33,0))+IF(BI45=0,0,IF(BI45<INICIO!$F$32*2,INICIO!$F$33,0))+IF(BI46=0,0,IF(BI46<INICIO!$F$32*2,INICIO!$F$33,0)) -> 0
A49: ARL | B49: =B47*2.436% -> 85260 | C49: =C47*2.436% -> 85260 | D49: =D47*2.436% -> 85260 | E49: =E47*2.436% -> 85260 | F49: =F47*2.436% -> 85260 | G49: =G47*2.436% -> 85260 | H49: =H47*2.436% -> 85260 | I49: =I47*2.436% -> 85260 | ... BI49: =BI47*2.436% -> 0
A50: EPS | B50: =B47*8.5% -> 297500 | C50: =C47*8.5% -> 297500 | D50: =D47*8.5% -> 297500 | E50: =E47*8.5% -> 297500 | F50: =F47*8.5% -> 297500 | G50: =G47*8.5% -> 297500 | H50: =H47*8.5% -> 297500 | I50: =I47*8.5% -> 297500 | ... BI50: =BI47*8.5% -> 0
A51: AFP | B51: =B47*12% -> 420000 | C51: =C47*12% -> 420000 | D51: =D47*12% -> 420000 | E51: =E47*12% -> 420000 | F51: =F47*12% -> 420000 | G51: =G47*12% -> 420000 | H51: =H47*12% -> 420000 | I51: =I47*12% -> 420000 | ... BI51: =BI47*12% -> 0
A52: Caja de Compensación | B52: =B47*4% -> 140000 | C52: =C47*4% -> 140000 | D52: =D47*4% -> 140000 | E52: =E47*4% -> 140000 | F52: =F47*4% -> 140000 | G52: =G47*4% -> 140000 | H52: =H47*4% -> 140000 | I52: =I47*4% -> 140000 | ... BI52: =BI47*4% -> 0
A53: Primas | B53: =B47*(100%/12) -> 291666.67 | C53: =C47*(100%/12) -> 291666.67 | D53: =D47*(100%/12) -> 291666.67 | E53: =E47*(100%/12) -> 291666.67 | F53: =F47*(100%/12) -> 291666.67 | G53: =G47*(100%/12) -> 291666.67 | H53: =H47*(100%/12) -> 291666.67 | I53: =I47*(100%/12) -> 291666.67 | ... BI53: =BI47*(100%/12) -> 0
A54: Cesantías | B54: =B47*(100%/12) -> 291666.67 | C54: =C47*(100%/12) -> 291666.67 | D54: =D47*(100%/12) -> 291666.67 | E54: =E47*(100%/12) -> 291666.67 | F54: =F47*(100%/12) -> 291666.67 | G54: =G47*(100%/12) -> 291666.67 | H54: =H47*(100%/12) -> 291666.67 | I54: =I47*(100%/12) -> 291666.67 | ... BI54: =BI47*(100%/12) -> 0
A55: Int a las Cesantías | B55: =B54*1% -> 2916.6667 | C55: =C54*1% -> 2916.6667 | D55: =D54*1% -> 2916.6667 | E55: =E54*1% -> 2916.6667 | F55: =F54*1% -> 2916.6667 | G55: =G54*1% -> 2916.6667 | H55: =H54*1% -> 2916.6667 | I55: =I54*1% -> 2916.6667 | ... BI55: =BI54*1% -> 0
A56: Vacaciones | B56: =B47*(100%/24) -> 145833.33 | C56: =C47*(100%/24) -> 145833.33 | D56: =D47*(100%/24) -> 145833.33 | E56: =E47*(100%/24) -> 145833.33 | F56: =F47*(100%/24) -> 145833.33 | G56: =G47*(100%/24) -> 145833.33 | H56: =H47*(100%/24) -> 145833.33 | I56: =I47*(100%/24) -> 145833.33 | ... BI56: =BI47*(100%/24) -> 0
A57: TOTAL PRESTACIONES (OPERATIVAS) | B57: =SUM(B48:B56) -> 1942843.3 | C57: =SUM(C48:C56) -> 1942843.3 | D57: =SUM(D48:D56) -> 1942843.3 | E57: =SUM(E48:E56) -> 1942843.3 | F57: =SUM(F48:F56) -> 1942843.3 | G57: =SUM(G48:G56) -> 1942843.3 | H57: =SUM(H48:H56) -> 1942843.3 | I57: =SUM(I48:I56) -> 1942843.3 | ... BI57: =SUM(BI48:BI56) -> 0
A60: PLAZO DE PAGO Y PLAZO DE INVENTARIOS | B60: =Año1 -> 2027 | N60: =Año2 -> 2028 | Z60: =Año3 -> 2029 | AL60: =Año4 -> 2030 | AX60: =Año5 -> 2031
B61: =B29 -> Mes 1 | C61: =C29 -> Mes 2 | D61: =D29 -> Mes 3 | E61: =E29 -> Mes 4 | F61: =F29 -> Mes 5 | G61: =G29 -> Mes 6 | H61: =H29 -> Mes 7 | I61: =I29 -> Mes 8 | ... BI61: =BI29 -> Mes 60
A62: Plazo que le otorgarán los proveedores para pagar (en días) | B62: 0 | C62: 0 | D62: 0 | E62: 0 | F62: 0 | G62: 0 | H62: 0 | I62: 0 | J62: 0 | K62: 0 | L62: 0 | M62: 0 | N62: 0 | O62: 0 | P62: 0 | Q62: 0 | R62: 0 | S62: 0 | T62: 0 | U62: 0 | V62: 0 | W62: 0 | X62: 0 | Y62: 0 | Z62: 0 | AA62: 0 | AB62: 0 | AC62: 0 | AD62: 0 | AE62: 0 | AF62: 0 | AG62: 0 | AH62: 0 | AI62: 0 | AJ62: 0 | AK62: 0 | AL62: 0 | AM62: 0 | AN62: 0 | AO62: 0 | AP62: 0 | AQ62: 0 | AR62: 0 | AS62: 0 | AT62: 0 | AU62: 0 | AV62: 0 | AW62: 0 | AX62: 0 | AY62: 0 | AZ62: 0 | BA62: 0 | BB62: 0 | BC62: 0 | BD62: 0 | BE62: 0 | BF62: 0 | BG62: 0 | BH62: 0 | BI62: 0
A63: Tiempo promedio en el que mantendrán inventarios (en días)
